Workbook
Name 客戶: [2]客戶編輯!$B$6:$AA$2243

Sheet 信封袋列印
D4: 客戶 (寄出信封)袋列印 | L4: 廠商 (寄出信封)袋列印
B5: 中華全佑有限公司 中華全威有限公司 全威企業社 苗栗縣竹南鎮中美里10鄰保安林52之15號 (037-463991) | I5: 中華全佑有限公司 中華全威有限公司 全威企業社 苗栗縣竹南鎮中美里10鄰保安林52之15號 (037-463991)
B6: 收件人 : | C6: =[1]客戶貨款總表!AT3 | D6: =[1]客戶貨款總表!AU3 | E6: =[1]客戶貨款總表!AV3 | I6: 收件人 : | J6: =[1]廠商貨款總表!AK9 | K6: =IF(J6="","",VLOOKUP(J6,[1]廠商編輯!$B$5:$S$3000,13,0)) | L6: =IF(J6="","",VLOOKUP(J6,[1]廠商編輯!$B$5:$S$3000,14,0)) | M6: 0
C7: =[1]客戶貨款總表!AT4 | D7: =[1]客戶貨款總表!AU4 | E7: =[1]客戶貨款總表!AV4 | M7: 0
C8: =[1]客戶貨款總表!AT5 | D8: =[1]客戶貨款總表!AU5 | E8: =[1]客戶貨款總表!AV5 | L8: =IF(J6="","",VLOOKUP(J6,[1]廠商編輯!$B$5:$S$3000,4,0)) | M8: 會計部 收
C9: =[1]客戶貨款總表!AT6 | D9: =[1]客戶貨款總表!AU6 | E9: =[1]客戶貨款總表!AV6 | G9: =[1]客戶貨款總表!AX6 | H9: =[1]客戶貨款總表!AY6 | M9: 0 | O9: =[1]客戶貨款總表!BF6
B10: 中華全佑有限公司 中華全威有限公司 全威企業社 苗栗縣竹南鎮中美里10鄰保安林52之15號 (037-463991) | G10: =[1]客戶貨款總表!AX7 | H10: =[1]客戶貨款總表!AY7 | M10: 0 | O10: =[1]客戶貨款總表!BF7
B11: 收件人 : | C11: =[1]客戶貨款總表!AX3 | D11: =[1]客戶貨款總表!AY3 | E11: =[1]客戶貨款總表!AZ3 | J11: =[1]廠商貨款總表!AK10 | K11: =IF(J11="","",VLOOKUP(J11,[1]廠商編輯!$B$5:$S$3000,13,0)) | L11: =IF(J11="","",VLOOKUP(J11,[1]廠商編輯!$B$5:$S$3000,14,0)) | M11: 0
C12: =[1]客戶貨款總表!AX4 | D12: =[1]客戶貨款總表!AU9 | E12: =[1]客戶貨款總表!AZ4 | M12: 0
C13: =[1]客戶貨款總表!AX5 | D13: =[1]客戶貨款總表!AY5 | E13: =[1]客戶貨款總表!AZ5 | L13: =IF(J11="","",VLOOKUP(J11,[1]廠商編輯!$B$5:$S$3000,4,0)) | M13: 會計部 收
C14: =[1]客戶貨款總表!AT11 | D14: =[1]客戶貨款總表!AU11 | E14: =[1]客戶貨款總表!AV11 | G14: =[1]客戶貨款總表!AX11 | H14: =[1]客戶貨款總表!AY11 | M14: 0 | O14: =[1]客戶貨款總表!BF11
A15: 中華全佑有限公司 中華全威有限公司 全威企業社 苗栗縣竹南鎮中美里10鄰保安林52之15號 (037-463991) | G15: =[1]客戶貨款總表!AX12 | H15: =[1]客戶貨款總表!AY12 | M15: 0 | O15: =[1]客戶貨款總表!BF12
B16: 收件人 : | C16: =[1]客戶貨款總表!AT8 | D16: =[1]客戶貨款總表!AU8 | E16: =[1]客戶貨款總表!AV8 | J16: =[1]廠商貨款總表!AK11 | K16: =IF(J16="","",VLOOKUP(J16,[1]廠商編輯!$B$5:$S$3000,13,0)) | L16: =IF(J16="","",VLOOKUP(J16,[1]廠商編輯!$B$5:$S$3000,14,0)) | M16: 0
C17: =[1]客戶貨款總表!AT9 | D17: =[1]客戶貨款總表!AU9 | E17: =[1]客戶貨款總表!AV9 | M17: 0
C18: =[1]客戶貨款總表!AT10 | D18: =[1]客戶貨款總表!AU10 | E18: =[1]客戶貨款總表!AV10 | L18: =IF(J16="","",VLOOKUP(J16,[1]廠商編輯!$B$5:$S$3000,4,0)) | M18: 會計部 收
B20: 中華全佑有限公司 中華全威有限公司 全威企業社 苗栗縣竹南鎮中美里10鄰保安林52之15號 (037-463991)
B21: 收件人 : | C21: =[1]客戶貨款總表!AX8 | D21: =[1]客戶貨款總表!AY8 | E21: =[1]客戶貨款總表!AZ8 | J21: =[1]廠商貨款總表!AK12 | K21: =IF(J21="","",VLOOKUP(J21,[1]廠商編輯!$B$5:$S$3000,13,0)) | L21: =IF(J21="","",VLOOKUP(J21,[1]廠商編輯!$B$5:$S$3000,14,0)) | M21: 0
C22: =[1]客戶貨款總表!AX9 | D22: =[1]客戶貨款總表!AY9 | E22: =[1]客戶貨款總表!AZ9 | M22: 0
C23: =[1]客戶貨款總表!AX10 | D23: =[1]客戶貨款總表!AY10 | E23: =[1]客戶貨款總表!AZ10 | L23: =IF(J21="","",VLOOKUP(J21,[1]廠商編輯!$B$5:$S$3000,4,0)) | M23: 會計部 收
B25: 中華全佑有限公司 中華全威有限公司 全威企業社 苗栗縣竹南鎮中美里10鄰保安林52之15號 (037-463991)
B26: 收件人 : | C26: =[1]客戶貨款總表!AT13 | D26: =[1]客戶貨款總表!AU13 | E26: =[1]客戶貨款總表!AV13 | M26: 0
C27: =[1]客戶貨款總表!AT14 | D27: =[1]客戶貨款總表!AU14 | E27: =[1]客戶貨款總表!AV14 | J27: =[1]廠商貨款總表!AK13 | K27: =IF(J27="","",VLOOKUP(J27,[1]廠商編輯!$B$5:$S$3000,13,0)) | L27: =IF(J27="","",VLOOKUP(J27,[1]廠商編輯!$B$5:$S$3000,14,0)) | M27: 0
C28: =[1]客戶貨款總表!AT15 | D28: =[1]客戶貨款總表!AU15 | E28: =[1]客戶貨款總表!AV15 | G28: =[1]客戶貨款總表!AX16 | H28: =[1]客戶貨款總表!AY16 | M28: 會計部 收 | O28: =[1]客戶貨款總表!BF16
C29: =[1]客戶貨款總表!AT17 | D29: =[1]客戶貨款總表!AU17 | E29: =[1]客戶貨款總表!AV17 | G29: =[1]客戶貨款總表!AX17 | H29: =[1]客戶貨款總表!AY17 | L29: =IF(J27="","",VLOOKUP(J27,[1]廠商編輯!$B$5:$S$3000,4,0)) | M29: 0 | O29: =[1]客戶貨款總表!BF17
B30: 中華全佑有限公司 中華全威有限公司 全威企業社 苗栗縣竹南鎮中美里10鄰保安林52之15號 (037-463991)
B31: 收件人 : | C31: =[1]客戶貨款總表!AX13 | D31: =[1]客戶貨款總表!AY13 | E31: =[1]客戶貨款總表!AZ13 | J31: =[1]廠商貨款總表!AK14 | K31: =IF(J31="","",VLOOKUP(J31,[1]廠商編輯!$B$5:$S$3000,13,0)) | L31: =IF(J31="","",VLOOKUP(J31,[1]廠商編輯!$B$5:$S$3000,14,0)) | M31: 0
C32: =[1]客戶貨款總表!AX14 | D32: =[1]客戶貨款總表!AY14 | E32: =[1]客戶貨款總表!AZ14 | M32: 0
C33: =[1]客戶貨款總表!AX15 | D33: =[1]客戶貨款總表!AY15 | E33: =[1]客戶貨款總表!AZ15 | L33: =IF(J31="","",VLOOKUP(J31,[1]廠商編輯!$B$5:$S$3000,4,0)) | M33: 會計部 收
B35: 中華全佑有限公司 中華全威有限公司 全威企業社 苗栗縣竹南鎮中美里10鄰保安林52之15號 (037-463991)
B36: 收件人 : | C36: =[1]客戶貨款總表!AT18 | D36: =[1]客戶貨款總表!AU18 | E36: =[1]客戶貨款總表!AV18 | J36: =[1]廠商貨款總表!AK15 | K36: =IF(J36="","",VLOOKUP(J36,[1]廠商編輯!$B$5:$S$3000,13,0)) | L36: =IF(J36="","",VLOOKUP(J36,[1]廠商編輯!$B$5:$S$3000,14,0)) | M36: 0
C37: =[1]客戶貨款總表!AT19 | D37: =[1]客戶貨款總表!AU19 | E37: =[1]客戶貨款總表!AV19 | M37: 0
C38: =[1]客戶貨款總表!AT20 | D38: =[1]客戶貨款總表!AU20 | E38: =[1]客戶貨款總表!AV20 | L38: =IF(J36="","",VLOOKUP(J36,[1]廠商編輯!$B$5:$S$3000,4,0)) | M38: 會計部 收
B40: 中華全佑有限公司 中華全威有限公司 全威企業社 苗栗縣竹南鎮中美里10鄰保安林52之15號 (037-463991)
B41: 收件人 : | C41: =[1]客戶貨款總表!AX18 | D41: =[1]客戶貨款總表!AY18 | E41: =[1]客戶貨款總表!AZ18 | J41: =[1]廠商貨款總表!AK16 | K41: =IF(J41="","",VLOOKUP(J41,[1]廠商編輯!$B$5:$S$3000,13,0)) | L41: =IF(J41="","",VLOOKUP(J41,[1]廠商編輯!$B$5:$S$3000,14,0)) | M41: 0
C42: =[1]客戶貨款總表!AX19 | D42: =[1]客戶貨款總表!AY19 | E42: =[1]客戶貨款總表!AZ19 | M42: 0
C43: =[1]客戶貨款總表!AX20 | D43: =[1]客戶貨款總表!AY20 | E43: =[1]客戶貨款總表!AZ20 | L43: =IF(J41="","",VLOOKUP(J41,[1]廠商編輯!$B$5:$S$3000,4,0)) | M43: 會計部 收
B45: 中華全佑有限公司 中華全威有限公司 全威企業社 苗栗縣竹南鎮中美里10鄰保安林52之15號 (037-463991)
B46: 收件人 : | C46: =[1]客戶貨款總表!AT23 | D46: =[1]客戶貨款總表!AU23 | E46: =[1]客戶貨款總表!AV23 | J46: =[1]廠商貨款總表!AK17 | K46: =IF(J46="","",VLOOKUP(J46,[1]廠商編輯!$B$5:$S$3000,13,0)) | L46: =IF(J46="","",VLOOKUP(J46,[1]廠商編輯!$B$5:$S$3000,14,0)) | M46: 0
C47: =[1]客戶貨款總表!AT24 | D47: =[1]客戶貨款總表!AU24 | E47: =[1]客戶貨款總表!AV24 | M47: 0
C48: =[1]客戶貨款總表!AT25 | D48: =[1]客戶貨款總表!AU25 | E48: =[1]客戶貨款總表!AV25 | L48: =IF(J46="","",VLOOKUP(J46,[1]廠商編輯!$B$5:$S$3000,4,0)) | M48: 會計部 收
...
