Workbook
Name 工作項目: 出貨單!$BX$6:$BY$250
Name 車號編輯: [1]客戶編輯!$AK$6:$AM$2243
Name 車頭: 出貨單!$BB$7:$BB$18
Name 板架: 出貨單!$BB$22:$BB$36
Name 客戶: [1]客戶編輯!$B$5:$AA$2243
Name 產品編輯: [1]產品編輯!$K$8:$KX$359
Name 產品編輯花紋: [1]產品編輯!$H$212:$FD$1101
Name 測試價: 出貨單!$AI$501
Name 進貨明細表: [1]進貨明細表!$AD$6:$AG$10000
Name 廠商: 出貨單!$CI$5:$CJ$1500
Name 廠商1: 出貨單!$CI$5:$CJ$1500
Name 廠商編輯: [1]廠商編輯!$B$6:$R$1499
Name 轎車: 出貨單!$BB$40:$BB$47

Sheet 出貨單˙收據
S1: 大車定位快速出貨檔
B2: 出貨單.合約書.收據 | K2: 中華全佑有限公司.中華全威有限公司.全威企業社.電話:037-463990 | P2: 出貨單.合約書.收據 | Y2: 中華全佑有限公司.中華全威有限公司.全威企業社.電話:037-463990
B4: 客戶名稱: | D4: =IF(C9="","",VLOOKUP(C9,出貨單!$E$5:$BV$20000,56,0)) | F4: 車頭公里數 : | G4: =IF(C9="","",VLOOKUP(C9,出貨單!$E$5:$BV$20000,8,0)) | I4: 出貨日期: | J4: =NOW() | P4: 客戶名稱: | R4: =IF(Q9="","",VLOOKUP(Q9,出貨單!$E$5:$BV$20000,56,0)) | T4: 車頭公里數 : | U4: =IF(Q9="","",VLOOKUP(Q9,出貨單!$E$5:$BV$20000,8,0)) | W4: 出貨日期: | X4: =NOW()
B5: 車牌號碼 : | D5: =IF(C9="","",VLOOKUP(C9,出貨單!$E$5:$BV$20000,2,0)) | F5: 工作人員: | G5: =IF(C9="","",VLOOKUP(C9,出貨單!$E$5:$BV$29813,46,0)) | I5: 車頭位置: | J5: =IF(C9="","",VLOOKUP(C9,出貨單!$E$5:$BV$20000,40,0)) | P5: 車牌號碼 : | R5: =IF(Q9="","",VLOOKUP(Q9,出貨單!$E$5:$BV$20000,2,0)) | T5: 工作人員: | U5: =IF(Q9="","",VLOOKUP(Q9,出貨單!$E$5:$BV$29813,46,0)) | W5: 車頭位置: | X5: =IF(Q9="","",VLOOKUP(Q9,出貨單!$E$5:$BV$20000,40,0))
B6: 工作時間 : | D6: =IF(C9="","",VLOOKUP(C9,出貨單!$E$5:$BV$20000,9,0)) | F6: 工作地點: | G6: =IF(C9="","",VLOOKUP(C9,出貨單!$E$5:$BV$20000,29,0)) | I6: 板架位置: | J6: =IF(C9="","",VLOOKUP(C9,出貨單!$E$5:$BV$20000,42,0)) | P6: 工作時間 : | R6: =IF(Q9="","",VLOOKUP(Q9,出貨單!$E$5:$BV$20000,9,0)) | T6: 工作地點: | U6: =IF(Q9="","",VLOOKUP(Q9,出貨單!$E$5:$BV$20000,29,0)) | W6: 板架位置: | X6: =IF(Q9="","",VLOOKUP(Q9,出貨單!$E$5:$BV$20000,42,0))
B7: 客戶地址 : | D7: =IF(D4="","",VLOOKUP(D4,[1]客戶編輯!$F$6:$Z$20000,20,0)) | F7: 報價人員: | G7: =IF(C9="","",VLOOKUP(C9,出貨單!$E$5:$BV$20000,22,0)) | I7: 轎.貨車位置: | J7: =IF(C9="","",VLOOKUP(C9,出貨單!$E$5:$BV$20000,44,0)) | P7: 客戶地址 : | R7: =IF(R4="","",VLOOKUP(R4,[1]客戶編輯!$F$6:$Z$20000,20,0)) | T7: 業務人員: | W7: 轎.貨車位置: | X7: =IF(Q9="","",VLOOKUP(Q9,出貨單!$E$5:$BV$20000,44,0))
B8: 序 | C8: 出貨單號 | D8: 維修內容 | E8: 廠牌. 規格. 花紋 | G8: 裝上胎號 | H8: 拆下胎號 | I8: 數量 | J8: 單價 | K8: 小計 | P8: 序 | Q8: 出貨單號 | R8: 維修內容 | S8: 廠牌. 規格. 花紋 | U8: 裝上胎號 | V8: 拆下胎號 | W8: 數量 | X8: 單價 | Y8: 小計
A9: 1 | B9: 1 | C9: 1100402004*1 | D9: =IF(C9="","",VLOOKUP(C9,出貨單!$E$5:$BV$29813,12,0)) | E9: =IF(C9="","",VLOOKUP(C9,出貨單!$E$5:$BV$29813,15,0)) | H9: =IF(C9="","",VLOOKUP(C9,出貨單!$E$5:$BV$29813,48,0)) | I9: =IF(C9="","",VLOOKUP(C9,出貨單!$E$5:$BV$29813,23,0)) | J9: =IF(C9="","",IF(VLOOKUP(C9,出貨單!$E$5:$BV$29813,26,0)=0,"-",VLOOKUP(C9,出貨單!$E$5:$BV$29813,26,0))) | K9: =IF(C9="","",IF(VLOOKUP(C9,出貨單!$E$5:$BV$29813,27,0)=0,"-",VLOOKUP(C9,出貨單!$E$5:$BV$29813,27,0))) | O9: 1 | P9: 1 | Q9: 1090518001*2 | R9: =IF(Q9="","",VLOOKUP(Q9,出貨單!$E$5:$BV$29813,12,0)) | S9: □*定位一式 | W9: =IF(Q9="","",VLOOKUP(Q9,出貨單!$E$5:$BV$29813,23,0))
A10: 2 | B10: 2 | C10: 1100402004*2 | D10: =IF(C10="","",VLOOKUP(C10,出貨單!$E$5:$BV$29813,12,0)) | E10: =IF(C10="","",VLOOKUP(C10,出貨單!$E$5:$BV$29813,15,0)) | H10: =IF(C10="","",VLOOKUP(C10,出貨單!$E$5:$BV$29813,48,0)) | I10: =IF(C10="","",VLOOKUP(C10,出貨單!$E$5:$BV$29813,23,0)) | J10: =IF(C10="","",IF(VLOOKUP(C10,出貨單!$E$5:$BV$29813,26,0)=0,"-",VLOOKUP(C10,出貨單!$E$5:$BV$29813,26,0))) | K10: =IF(C10="","",IF(VLOOKUP(C10,出貨單!$E$5:$BV$29813,27,0)=0,"-",VLOOKUP(C10,出貨單!$E$5:$BV$29813,27,0))) | O10: 2 | P10: 2 | R10: =IF(Q10="","",VLOOKUP(Q10,出貨單!$E$5:$BV$29813,12,0)) | S10: □*前束調整 | W10: =IF(Q10="","",VLOOKUP(Q10,出貨單!$E$5:$BV$29813,23,0))
A11: 3 | B11: 3 | D11: =IF(C11="","",VLOOKUP(C11,出貨單!$E$5:$BV$29813,12,0)) | E11: =IF(C11="","",VLOOKUP(C11,出貨單!$E$5:$BV$29813,15,0)) | H11: =IF(C11="","",VLOOKUP(C11,出貨單!$E$5:$BV$29813,48,0)) | I11: =IF(C11="","",VLOOKUP(C11,出貨單!$E$5:$BV$29813,23,0)) | J11: =IF(C11="","",IF(VLOOKUP(C11,出貨單!$E$5:$BV$29813,26,0)=0,"-",VLOOKUP(C11,出貨單!$E$5:$BV$29813,26,0))) | K11: =IF(C11="","",IF(VLOOKUP(C11,出貨單!$E$5:$BV$29813,27,0)=0,"-",VLOOKUP(C11,出貨單!$E$5:$BV$29813,27,0))) | O11: 3 | P11: 3 | R11: =IF(Q11="","",VLOOKUP(Q11,出貨單!$E$5:$BV$29813,12,0)) | S11: □*方向盤調整 | W11: =IF(Q11="","",VLOOKUP(Q11,出貨單!$E$5:$BV$29813,23,0)) | X11: =IF(Q11="","",VLOOKUP(Q11,出貨單!$E$5:$BV$29813,26,0)) | Y11: =IF(Q11="","",VLOOKUP(Q11,出貨單!$E$5:$BV$29813,27,0))
A12: 4 | B12: 4 | D12: =IF(C12="","",VLOOKUP(C12,出貨單!$E$5:$BV$29813,12,0)) | E12: =IF(C12="","",VLOOKUP(C12,出貨單!$E$5:$BV$29813,15,0)) | H12: =IF(C12="","",VLOOKUP(C12,出貨單!$E$5:$BV$29813,48,0)) | I12: =IF(C12="","",VLOOKUP(C12,出貨單!$E$5:$BV$29813,23,0)) | J12: =IF(C12="","",IF(VLOOKUP(C12,出貨單!$E$5:$BV$29813,26,0)=0,"-",VLOOKUP(C12,出貨單!$E$5:$BV$29813,26,0))) | K12: =IF(C12="","",IF(VLOOKUP(C12,出貨單!$E$5:$BV$29813,27,0)=0,"-",VLOOKUP(C12,出貨單!$E$5:$BV$29813,27,0))) | O12: 4 | P12: 4 | R12: =IF(Q12="","",VLOOKUP(Q12,出貨單!$E$5:$BV$29813,12,0)) | S12: □*後傾角調整 | W12: =IF(Q12="","",VLOOKUP(Q12,出貨單!$E$5:$BV$29813,23,0)) | X12: =IF(Q12="","",VLOOKUP(Q12,出貨單!$E$5:$BV$29813,26,0)) | Y12: =IF(Q12="","",VLOOKUP(Q12,出貨單!$E$5:$BV$29813,27,0))
A13: 5 | B13: 5 | D13: =IF(C13="","",VLOOKUP(C13,出貨單!$E$5:$BV$29813,12,0)) | E13: =IF(C13="","",VLOOKUP(C13,出貨單!$E$5:$BV$29813,15,0)) | H13: =IF(C13="","",VLOOKUP(C13,出貨單!$E$5:$BV$29813,48,0)) | I13: =IF(C13="","",VLOOKUP(C13,出貨單!$E$5:$BV$29813,23,0)) | J13: =IF(C13="","",IF(VLOOKUP(C13,出貨單!$E$5:$BV$29813,26,0)=0,"-",VLOOKUP(C13,出貨單!$E$5:$BV$29813,26,0))) | K13: =IF(C13="","",IF(VLOOKUP(C13,出貨單!$E$5:$BV$29813,27,0)=0,"-",VLOOKUP(C13,出貨單!$E$5:$BV$29813,27,0))) | O13: 5 | P13: 5 | R13: =IF(Q13="","",VLOOKUP(Q13,出貨單!$E$5:$BV$29813,12,0)) | S13: □*後傾角墊片 | W13: =IF(Q13="","",VLOOKUP(Q13,出貨單!$E$5:$BV$29813,23,0)) | X13: =IF(Q13="","",VLOOKUP(Q13,出貨單!$E$5:$BV$29813,26,0)) | Y13: =IF(Q13="","",VLOOKUP(Q13,出貨單!$E$5:$BV$29813,27,0))
A14: 6 | B14: 6 | D14: =IF(C14="","",VLOOKUP(C14,出貨單!$E$5:$BV$29813,12,0)) | E14: =IF(C14="","",VLOOKUP(C14,出貨單!$E$5:$BV$29813,15,0)) | H14: =IF(C14="","",VLOOKUP(C14,出貨單!$E$5:$BV$29813,48,0)) | I14: =IF(C14="","",VLOOKUP(C14,出貨單!$E$5:$BV$29813,23,0)) | J14: =IF(C14="","",IF(VLOOKUP(C14,出貨單!$E$5:$BV$29813,26,0)=0,"-",VLOOKUP(C14,出貨單!$E$5:$BV$29813,26,0))) | K14: =IF(C14="","",IF(VLOOKUP(C14,出貨單!$E$5:$BV$29813,27,0)=0,"-",VLOOKUP(C14,出貨單!$E$5:$BV$29813,27,0))) | O14: 6 | P14: 6 | R14: =IF(Q14="","",VLOOKUP(Q14,出貨單!$E$5:$BV$29813,12,0)) | S14: □*工字樑校正 | W14: =IF(Q14="","",VLOOKUP(Q14,出貨單!$E$5:$BV$29813,23,0)) | X14: =IF(Q14="","",VLOOKUP(Q14,出貨單!$E$5:$BV$29813,26,0)) | Y14: =IF(Q14="","",VLOOKUP(Q14,出貨單!$E$5:$BV$29813,27,0))
A15: 7 | B15: 7 | D15: =IF(C15="","",VLOOKUP(C15,出貨單!$E$5:$BV$29813,12,0)) | E15: =IF(C15="","",VLOOKUP(C15,出貨單!$E$5:$BV$29813,15,0)) | H15: =IF(C15="","",VLOOKUP(C15,出貨單!$E$5:$BV$29813,48,0)) | I15: =IF(C15="","",VLOOKUP(C15,出貨單!$E$5:$BV$29813,23,0)) | J15: =IF(C15="","",IF(VLOOKUP(C15,出貨單!$E$5:$BV$29813,26,0)=0,"-",VLOOKUP(C15,出貨單!$E$5:$BV$29813,26,0))) | K15: =IF(C15="","",IF(VLOOKUP(C15,出貨單!$E$5:$BV$29813,27,0)=0,"-",VLOOKUP(C15,出貨單!$E$5:$BV$29813,27,0))) | O15: 7 | P15: 7 | R15: =IF(Q15="","",VLOOKUP(Q15,出貨單!$E$5:$BV$29813,12,0)) | S15: □*軸距調整 | W15: =IF(Q15="","",VLOOKUP(Q15,出貨單!$E$5:$BV$29813,23,0)) | X15: =IF(Q15="","",VLOOKUP(Q15,出貨單!$E$5:$BV$29813,26,0)) | Y15: =IF(Q15="","",VLOOKUP(Q15,出貨單!$E$5:$BV$29813,27,0))
A16: 8 | B16: 8 | D16: =IF(C16="","",VLOOKUP(C16,出貨單!$E$5:$BV$29813,12,0)) | E16: =IF(C16="","",VLOOKUP(C16,出貨單!$E$5:$BV$29813,15,0)) | H16: =IF(C16="","",VLOOKUP(C16,出貨單!$E$5:$BV$29813,48,0)) | I16: =IF(C16="","",VLOOKUP(C16,出貨單!$E$5:$BV$29813,23,0)) | J16: =IF(C16="","",IF(VLOOKUP(C16,出貨單!$E$5:$BV$29813,26,0)=0,"-",VLOOKUP(C16,出貨單!$E$5:$BV$29813,26,0))) | K16: =IF(C16="","",IF(VLOOKUP(C16,出貨單!$E$5:$BV$29813,27,0)=0,"-",VLOOKUP(C16,出貨單!$E$5:$BV$29813,27,0))) | O16: 8 | P16: 8 | Q16: 1090518001*1 | R16: =IF(Q16="","",VLOOKUP(Q16,出貨單!$E$5:$BV$29813,12,0)) | S16: =IF(Q16="","",VLOOKUP(Q16,出貨單!$E$5:$BV$29813,15,0)) | W16: =IF(Q16="","",VLOOKUP(Q16,出貨單!$E$5:$BV$29813,23,0)) | X16: =IF(Q16="","",VLOOKUP(Q16,出貨單!$E$5:$BV$29813,26,0)) | Y16: =IF(Q16="","",VLOOKUP(Q16,出貨單!$E$5:$BV$29813,27,0))
A17: 9 | B17: 9 | D17: =IF(C17="","",VLOOKUP(C17,出貨單!$E$5:$BV$29813,12,0)) | E17: =IF(C17="","",VLOOKUP(C17,出貨單!$E$5:$BV$29813,15,0)) | H17: =IF(C17="","",VLOOKUP(C17,出貨單!$E$5:$BV$29813,48,0)) | I17: =IF(C17="","",VLOOKUP(C17,出貨單!$E$5:$BV$29813,23,0)) | J17: =IF(C17="","",IF(VLOOKUP(C17,出貨單!$E$5:$BV$29813,26,0)=0,"-",VLOOKUP(C17,出貨單!$E$5:$BV$29813,26,0))) | K17: =IF(C17="","",IF(VLOOKUP(C17,出貨單!$E$5:$BV$29813,27,0)=0,"-",VLOOKUP(C17,出貨單!$E$5:$BV$29813,27,0))) | O17: 9 | P17: 9 | R17: =IF(Q17="","",VLOOKUP(Q17,出貨單!$E$5:$BV$29813,12,0)) | S17: =IF(Q17="","",VLOOKUP(Q17,出貨單!$E$5:$BV$29813,15,0)) | W17: =IF(Q17="","",VLOOKUP(Q17,出貨單!$E$5:$BV$29813,23,0)) | X17: =IF(Q17="","",VLOOKUP(Q17,出貨單!$E$5:$BV$29813,26,0)) | Y17: =IF(Q17="","",VLOOKUP(Q17,出貨單!$E$5:$BV$29813,27,0))
B18: 10 | D18: =IF(C18="","",VLOOKUP(C18,出貨單!$E$5:$BV$29813,12,0)) | E18: =IF(C18="","",VLOOKUP(C18,出貨單!$E$5:$BV$29813,15,0)) | H18: =IF(C18="","",VLOOKUP(C18,出貨單!$E$5:$BV$29813,48,0)) | I18: =IF(C18="","",VLOOKUP(C18,出貨單!$E$5:$BV$29813,23,0)) | J18: =IF(C18="","",IF(VLOOKUP(C18,出貨單!$E$5:$BV$29813,26,0)=0,"-",VLOOKUP(C18,出貨單!$E$5:$BV$29813,26,0))) | K18: =IF(C18="","",IF(VLOOKUP(C18,出貨單!$E$5:$BV$29813,27,0)=0,"-",VLOOKUP(C18,出貨單!$E$5:$BV$29813,27,0))) | P18: 10 | R18: =IF(Q18="","",VLOOKUP(Q18,出貨單!$E$5:$BV$29813,12,0)) | S18: =IF(Q18="","",VLOOKUP(Q18,出貨單!$E$5:$BV$29813,15,0)) | W18: =IF(Q18="","",VLOOKUP(Q18,出貨單!$E$5:$BV$29813,23,0)) | X18: =IF(Q18="","",VLOOKUP(Q18,出貨單!$E$5:$BV$29813,26,0)) | Y18: =IF(Q18="","",VLOOKUP(Q18,出貨單!$E$5:$BV$29813,27,0))
B19: 小計金額 | K19: =SUM(K9:K18) | P19: 小計金額 | Y19: =SUM(Y9:Y18)
B20: 客戶簽名： | E20: 老闆簽核： | G20: 稅額: | H20: =IF(OR(I20="含稅",I20="未稅"),0,IF(OR(I20="稅外"),K19*0.05,"")) | I20: =IF(C9="","",VLOOKUP(C9,出貨單!$E$5:$BV$29813,34,0)) | J20: 總計: | K20: =IF(OR(K19>0.1),K19+H20,IF(OR(K19=0),K19,"")) | P20: 客戶簽名： | S20: 老闆簽核： | U20: 稅額: | V20: =IF(OR(W20="含稅",W20="未稅"),0,IF(OR(W20="稅外"),Y19*0.05,"")) | W20: =IF(Q9="","",VLOOKUP(Q9,出貨單!$E$5:$BV$29813,34,0)) | X20: 總計: | Y20: =IF(OR(Y19>0.1),Y19+V20,IF(OR(Y19=0),Y19,""))
C22: 1.本公司無到府牽車來回或試車來回服務，由客戶自行送修來本廠區及自行取回車輛，客戶拜託本廠內工作人員去牽車來回 | Q22: 1.本公司無到府牽車來回或試車來回服務，由客戶自行送修來本廠區及自行取回車輛，客戶拜託本廠內工作人員去牽車來回
C23: 或試車來回時，發生意外全部損失費用由車主自行負責。車輛進本廠區維修時，車上之重要物品請客戶自行保管，有損毀遺 | Q23: 或試車來回時，發生意外全部損失費用由車主自行負責。車輛進本廠區維修時，車上之重要物品請客戶自行保管，有損毀遺
B24: 備 | C24: 失時車主自行負責。客戶交修車輛需自行保險，發生天災地變或其他不可抗力之災損本公司不負賠償責任。車主不得異議。 | P24: 備 | Q24: 失時車主自行負責。客戶交修車輛需自行保險，發生天災地變或其他不可抗力之災損本公司不負賠償責任。車主不得異議。
B25: 註 | C25: 2.以上貨品貨款尚未付清時，產品所有權仍為本公司所有本公司可無條件收回銷售產品，寄放新輪胎新鋼圈或中古輪胎中古 | P25: 註 | Q25: 2.以上貨品貨款尚未付清時，產品所有權仍為本公司所有本公司可無條件收回銷售產品，寄放新輪胎新鋼圈或中古輪胎中古
C26: 鋼圈，期限最長3個月超過期限，不領取以廢輪胎方式丟棄，車輛換下之廢輪胎若需保留者請自行當下載回，不載回者視同 | Q26: 鋼圈，期限最長3個月超過期限，不領取以廢輪胎方式丟棄，車輛換下之廢輪胎若需保留者請自行當下載回，不載回者視同
C27: 丟棄。領取新輪胎新鋼圈或中古輪胎中古鋼圈時必須以簽單為憑證，無簽單者視同丟棄不得異議。存根(白)請款(黃)客戶(藍) | Q27: 丟棄。領取新輪胎新鋼圈或中古輪胎中古鋼圈時必須以簽單為憑證，無簽單者視同丟棄不得異議。存根(白)請款(黃)客戶(藍)
M28: 批發出貨檔 | S28: 空白出貨檔
B29: 出貨單.合約書.收據 | K29: 中華全佑有限公司.中華全威有限公司.全威企業社.電話:037-463990 | P29: 出貨單.合約書.收據 | Y29: 中華全佑有限公司.中華全威有限公司.全威企業社.電話:037-463990
B31: 客戶名稱: | D31: =IF(C36="","",VLOOKUP(C36,出貨單!$E$5:$BV$20000,56,0)) | F31: 車頭公里數 : | G31: =IF(C36="","",VLOOKUP(C36,出貨單!$E$5:$BV$20000,8,0)) | I31: 出貨日期: | J31: =NOW() | L31: . | P31: 客戶名稱: | R31: 廠商20 大城 | T31: 車頭公里數 : | W31: 出貨日期: | X31: =NOW()
B32: 車牌號碼 : | D32: =IF(C36="","",VLOOKUP(C36,出貨單!$E$5:$BV$20000,2,0)) | F32: 工作人員: | G32: =IF(C36="","",VLOOKUP(C36,出貨單!$E$5:$BV$29813,46,0)) | I32: 車頭位置: | J32: =IF(C36="","",VLOOKUP(C36,出貨單!$E$5:$BV$20000,40,0)) | P32: 車牌號碼 : | T32: 工作人員: | W32: 車頭位置:
B33: 工作時間 : | D33: =IF(C36="","",VLOOKUP(C36,出貨單!$E$5:$BV$20000,9,0)) | F33: 工作地點: | G33: =IF(C36="","",VLOOKUP(C36,出貨單!$E$5:$BV$20000,29,0)) | I33: 板架位置: | J33: =IF(C36="","",VLOOKUP(C36,出貨單!$E$5:$BV$20000,42,0)) | P33: 工作時間 : | T33: 工作地點: | W33: 板架位置:
B34: 客戶地址 : | D34: =IF(D31="","",VLOOKUP(D31,[1]客戶編輯!$F$6:$Z$20000,20,0)) | F34: 報價人員: | G34: =IF(C36="","",VLOOKUP(C36,出貨單!$E$5:$BV$20000,22,0)) | I34: 轎.貨車位置: | J34: =IF(C36="","",VLOOKUP(C36,出貨單!$E$5:$BV$20000,44,0)) | P34: 客戶地址 : | R34: =IF(R31="","",VLOOKUP(R31,[1]客戶編輯!$F$6:$Z$20000,20,0)) | T34: 業務人員: | W34: 轎.貨車位置:
B35: 序 | C35: 出貨單號 | D35: 維修內容 | E35: 廠牌. 規格. 花紋 | G35: 胎號 | H35: 備註 | I35: 數量 | J35: 單價 | K35: 小計 | P35: 序 | Q35: 出貨單號 | R35: 維修內容 | S35: 廠牌. 規格. 花紋 | U35: 裝上胎號 | V35: 拆下胎號 | W35: 數量 | X35: 單價 | Y35: 小計
A36: 1 | B36: 1 | C36: 1100402006 | D36: =IF(C36="","",VLOOKUP(C36,出貨單!$E$5:$BV$29813,12,0)) | E36: =IF(C36="","",VLOOKUP(C36,出貨單!$E$5:$BV$29813,15,0)) | H36: =IF(C36="","",VLOOKUP(C36,出貨單!$E$5:$BV$29813,31,0)) | I36: =IF(C36="","",VLOOKUP(C36,出貨單!$E$5:$BV$29813,23,0)) | J36: =IF(C36="","",IF(VLOOKUP(C36,出貨單!$E$5:$BV$29813,26,0)=0,"-",VLOOKUP(C36,出貨單!$E$5:$BV$29813,26,0))) | K36: =IF(C36="","",IF(VLOOKUP(C36,出貨單!$E$5:$BV$29813,27,0)=0,"-",VLOOKUP(C36,出貨單!$E$5:$BV$29813,27,0))) | O36: 1 | P36: 1 | Q36: 1090407002 | S36: 鏡頭不能開機 | W36: 1 | X36: =IF(Q36="","",VLOOKUP(Q36,出貨單!$E$5:$BV$29813,26,0)) | Y36: =IF(Q36="","",VLOOKUP(Q36,出貨單!$E$5:$BV$29813,27,0))
A37: 2 | B37: 2 | D37: =IF(C37="","",VLOOKUP(C37,出貨單!$E$5:$BV$29813,12,0)) | E37: =IF(C37="","",VLOOKUP(C37,出貨單!$E$5:$BV$29813,15,0)) | H37: =IF(C37="","",VLOOKUP(C37,出貨單!$E$5:$BV$29813,31,0)) | I37: =IF(C37="","",VLOOKUP(C37,出貨單!$E$5:$BV$29813,23,0)) | J37: =IF(C37="","",IF(VLOOKUP(C37,出貨單!$E$5:$BV$29813,26,0)=0,"-",VLOOKUP(C37,出貨單!$E$5:$BV$29813,26,0))) | K37: =IF(C37="","",IF(VLOOKUP(C37,出貨單!$E$5:$BV$29813,27,0)=0,"-",VLOOKUP(C37,出貨單!$E$5:$BV$29813,27,0))) | O37: 2 | P37: 2 | R37: =IF(Q37="","",VLOOKUP(Q37,出貨單!$E$5:$BV$29813,12,0)) | S37: =IF(Q37="","",VLOOKUP(Q37,出貨單!$E$5:$BV$29813,15,0)) | W37: =IF(Q37="","",VLOOKUP(Q37,出貨單!$E$5:$BV$29813,23,0)) | X37: =IF(Q37="","",VLOOKUP(Q37,出貨單!$E$5:$BV$29813,26,0)) | Y37: =IF(Q37="","",VLOOKUP(Q37,出貨單!$E$5:$BV$29813,27,0))
A38: 3 | B38: 3 | D38: =IF(C38="","",VLOOKUP(C38,出貨單!$E$5:$BV$29813,12,0)) | E38: =IF(C38="","",VLOOKUP(C38,出貨單!$E$5:$BV$29813,15,0)) | H38: =IF(C38="","",VLOOKUP(C38,出貨單!$E$5:$BV$29813,31,0)) | I38: =IF(C38="","",VLOOKUP(C38,出貨單!$E$5:$BV$29813,23,0)) | J38: =IF(C38="","",IF(VLOOKUP(C38,出貨單!$E$5:$BV$29813,26,0)=0,"-",VLOOKUP(C38,出貨單!$E$5:$BV$29813,26,0))) | K38: =IF(C38="","",IF(VLOOKUP(C38,出貨單!$E$5:$BV$29813,27,0)=0,"-",VLOOKUP(C38,出貨單!$E$5:$BV$29813,27,0))) | O38: 3 | P38: 3 | R38: =IF(Q38="","",VLOOKUP(Q38,出貨單!$E$5:$BV$29813,12,0)) | S38: =IF(Q38="","",VLOOKUP(Q38,出貨單!$E$5:$BV$29813,15,0)) | W38: =IF(Q38="","",VLOOKUP(Q38,出貨單!$E$5:$BV$29813,23,0)) | X38: =IF(Q38="","",VLOOKUP(Q38,出貨單!$E$5:$BV$29813,26,0)) | Y38: =IF(Q38="","",VLOOKUP(Q38,出貨單!$E$5:$BV$29813,27,0))
A39: 4 | B39: 4 | D39: =IF(C39="","",VLOOKUP(C39,出貨單!$E$5:$BV$29813,12,0)) | E39: =IF(C39="","",VLOOKUP(C39,出貨單!$E$5:$BV$29813,15,0)) | H39: =IF(C39="","",VLOOKUP(C39,出貨單!$E$5:$BV$29813,31,0)) | I39: =IF(C39="","",VLOOKUP(C39,出貨單!$E$5:$BV$29813,23,0)) | J39: =IF(C39="","",IF(VLOOKUP(C39,出貨單!$E$5:$BV$29813,26,0)=0,"-",VLOOKUP(C39,出貨單!$E$5:$BV$29813,26,0))) | K39: =IF(C39="","",IF(VLOOKUP(C39,出貨單!$E$5:$BV$29813,27,0)=0,"-",VLOOKUP(C39,出貨單!$E$5:$BV$29813,27,0))) | O39: 4 | P39: 4 | R39: =IF(Q39="","",VLOOKUP(Q39,出貨單!$E$5:$BV$29813,12,0)) | S39: =IF(Q39="","",VLOOKUP(Q39,出貨單!$E$5:$BV$29813,15,0)) | W39: =IF(Q39="","",VLOOKUP(Q39,出貨單!$E$5:$BV$29813,23,0)) | X39: =IF(Q39="","",VLOOKUP(Q39,出貨單!$E$5:$BV$29813,26,0)) | Y39: =IF(Q39="","",VLOOKUP(Q39,出貨單!$E$5:$BV$29813,27,0))
A40: 5 | B40: 5 | D40: =IF(C40="","",VLOOKUP(C40,出貨單!$E$5:$BV$29813,12,0)) | E40: =IF(C40="","",VLOOKUP(C40,出貨單!$E$5:$BV$29813,15,0)) | H40: =IF(C40="","",VLOOKUP(C40,出貨單!$E$5:$BV$29813,31,0)) | I40: =IF(C40="","",VLOOKUP(C40,出貨單!$E$5:$BV$29813,23,0)) | J40: =IF(C40="","",IF(VLOOKUP(C40,出貨單!$E$5:$BV$29813,26,0)=0,"-",VLOOKUP(C40,出貨單!$E$5:$BV$29813,26,0))) | K40: =IF(C40="","",IF(VLOOKUP(C40,出貨單!$E$5:$BV$29813,27,0)=0,"-",VLOOKUP(C40,出貨單!$E$5:$BV$29813,27,0))) | O40: 5 | P40: 5 | R40: =IF(Q40="","",VLOOKUP(Q40,出貨單!$E$5:$BV$29813,12,0)) | S40: =IF(Q40="","",VLOOKUP(Q40,出貨單!$E$5:$BV$29813,15,0)) | W40: =IF(Q40="","",VLOOKUP(Q40,出貨單!$E$5:$BV$29813,23,0)) | X40: =IF(Q40="","",VLOOKUP(Q40,出貨單!$E$5:$BV$29813,26,0)) | Y40: =IF(Q40="","",VLOOKUP(Q40,出貨單!$E$5:$BV$29813,27,0))
A41: 6 | B41: 6 | D41: =IF(C41="","",VLOOKUP(C41,出貨單!$E$5:$BV$29813,12,0)) | E41: =IF(C41="","",VLOOKUP(C41,出貨單!$E$5:$BV$29813,15,0)) | H41: =IF(C41="","",VLOOKUP(C41,出貨單!$E$5:$BV$29813,31,0)) | I41: =IF(C41="","",VLOOKUP(C41,出貨單!$E$5:$BV$29813,23,0)) | J41: =IF(C41="","",IF(VLOOKUP(C41,出貨單!$E$5:$BV$29813,26,0)=0,"-",VLOOKUP(C41,出貨單!$E$5:$BV$29813,26,0))) | K41: =IF(C41="","",IF(VLOOKUP(C41,出貨單!$E$5:$BV$29813,27,0)=0,"-",VLOOKUP(C41,出貨單!$E$5:$BV$29813,27,0))) | O41: 6 | P41: 6 | R41: =IF(Q41="","",VLOOKUP(Q41,出貨單!$E$5:$BV$29813,12,0)) | S41: =IF(Q41="","",VLOOKUP(Q41,出貨單!$E$5:$BV$29813,15,0)) | W41: =IF(Q41="","",VLOOKUP(Q41,出貨單!$E$5:$BV$29813,23,0)) | X41: =IF(Q41="","",VLOOKUP(Q41,出貨單!$E$5:$BV$29813,26,0)) | Y41: =IF(Q41="","",VLOOKUP(Q41,出貨單!$E$5:$BV$29813,27,0))
A42: 7 | B42: 7 | D42: =IF(C42="","",VLOOKUP(C42,出貨單!$E$5:$BV$29813,12,0)) | E42: =IF(C42="","",VLOOKUP(C42,出貨單!$E$5:$BV$29813,15,0)) | H42: =IF(C42="","",VLOOKUP(C42,出貨單!$E$5:$BV$29813,31,0)) | I42: =IF(C42="","",VLOOKUP(C42,出貨單!$E$5:$BV$29813,23,0)) | J42: =IF(C42="","",IF(VLOOKUP(C42,出貨單!$E$5:$BV$29813,26,0)=0,"-",VLOOKUP(C42,出貨單!$E$5:$BV$29813,26,0))) | K42: =IF(C42="","",IF(VLOOKUP(C42,出貨單!$E$5:$BV$29813,27,0)=0,"-",VLOOKUP(C42,出貨單!$E$5:$BV$29813,27,0))) | O42: 7 | P42: 7 | R42: =IF(Q42="","",VLOOKUP(Q42,出貨單!$E$5:$BV$29813,12,0)) | S42: =IF(Q42="","",VLOOKUP(Q42,出貨單!$E$5:$BV$29813,15,0)) | W42: =IF(Q42="","",VLOOKUP(Q42,出貨單!$E$5:$BV$29813,23,0)) | X42: =IF(Q42="","",VLOOKUP(Q42,出貨單!$E$5:$BV$29813,26,0)) | Y42: =IF(Q42="","",VLOOKUP(Q42,出貨單!$E$5:$BV$29813,27,0))
A43: 8 | B43: 8 | D43: =IF(C43="","",VLOOKUP(C43,出貨單!$E$5:$BV$29813,12,0)) | E43: =IF(C43="","",VLOOKUP(C43,出貨單!$E$5:$BV$29813,15,0)) | H43: =IF(C43="","",VLOOKUP(C43,出貨單!$E$5:$BV$29813,31,0)) | I43: =IF(C43="","",VLOOKUP(C43,出貨單!$E$5:$BV$29813,23,0)) | J43: =IF(C43="","",IF(VLOOKUP(C43,出貨單!$E$5:$BV$29813,26,0)=0,"-",VLOOKUP(C43,出貨單!$E$5:$BV$29813,26,0))) | K43: =IF(C43="","",IF(VLOOKUP(C43,出貨單!$E$5:$BV$29813,27,0)=0,"-",VLOOKUP(C43,出貨單!$E$5:$BV$29813,27,0))) | O43: 8 | P43: 8 | R43: =IF(Q43="","",VLOOKUP(Q43,出貨單!$E$5:$BV$29813,12,0)) | S43: =IF(Q43="","",VLOOKUP(Q43,出貨單!$E$5:$BV$29813,15,0)) | W43: =IF(Q43="","",VLOOKUP(Q43,出貨單!$E$5:$BV$29813,23,0)) | X43: =IF(Q43="","",VLOOKUP(Q43,出貨單!$E$5:$BV$29813,26,0)) | Y43: =IF(Q43="","",VLOOKUP(Q43,出貨單!$E$5:$BV$29813,27,0))
...
