Workbook

Sheet 客戶編輯設定自動代出
A1: 客編 | B1: 統一編號 | C1: 客名
A2: 1 | B2: 27911467 | C2: 全佑
A3: 2 | B3: 13356334 | C3: 緯達
A4: 3 | B4: 86328102 | C4: 榮聯
A5: 4 | B5: 89323593 | C5: 長增
A6: 6 | B6: 37008102 | C6: 長呈王
A7: 7 | B7: 70700940 | C7: 宜城
A8: 8 | C8: 路人
A9: 9 | B9: 78549932 | C9: 大豐
A10: 10 | B10: 98152228 | C10: 永業
A11: 11 | B11: 94935622 | C11: 海銓
A12: 12 | B12: 80239244 | C12: 益順
A13: 12 | B13: 84218410 | C13: 益順
A14: 13 | B14: 28053034 | C14: 高譜
A15: 14 | B15: 80967051 | C15: 順合
A16: 14 | B16: 53789414 | C16: 六順
A17: 15 | B17: 92841607 | C17: 志祥
A18: 16 | B18: 23795614 | C18: 竹升
A19: 17 | B19: 45555665 | C19: 林富國
A20: 18 | B20: 84707607 | C20: 輝業
... A57: 53 | B57: 12928623 | C57: 力璽
A58: 54-2 | B58: 54965579 | C58: 宜群
A59: 54-1 | B59: 89659962 | C59: 美聖
A60: 55 | B60: 33928331 | C60: 邱金海
A61: 56 | B61: 22542535 | C61: 寬輾
A62: 58 | B62: 13007548 | C62: 鑫能
A63: 60 | B63: 45654692 | C63: 源鴻
A64: 61 | B64: 50516214 | C64: 信豐
A65: 62 | B65: 28101628 | C65: 至懋
A66: 63 | B66: 50511800 | C66: 德緯
A67: 64 | B67: 21491798 | C67: 順祥吊車
A68: 65 | B68: 39676282 | C68: 台澄郭董＞寄
A69: 66 | B69: 16752907 | C69: 豪泰
A70: 67 | B70: 45823965 | C70: 小阿姨
A71: 68 | B71: 98786399 | C71: 台北輝
A72: 69 | B72: 02851499 | C72: 佳金卓文湧
A73: 70 | B73: 49810267 | C73: 佳弘曾錦忠
A74: 72 | B74: 09947702 | C74: 源勝皓弟
A75: 73 | B75: 24634341 | C75: 李志文菜車
A76: 74 | B76: 50160585 | C76: 順安
...

Sheet 廠商編輯設定自動代出
A1: NO | B1: 名稱 | C1: 統一編號
A2: 3 | B2: 東大 | C2: 35190441
A3: 4 | B3: 建發 | C3: 75349375
A4: 5 | B4: 米其林(公司)-大胎 | C4: 70357185
A5: 6 | B5: 米其林(公司)-中胎 | C5: 70357185
A6: 7 | B6: 米其林(公司)-小胎 | C6: 70357185
A7: 8 | B7: 米其林(工程胎)-翻修胎 | C7: 11383200
A8: 9 | B8: 利坤-上眾 | C8: 89878729
A9: 10 | B9: 吉喆-來令片 | C9: -
A10: 11 | B10: 南鴻 | C10: 84263300
A11: 12 | B11: 互.富信行 | C11: 12315075
A12: 13 | B12: 大勁 | C12: 53789792
A13: 14 | B13: 福輪 | C13: 29060435
A14: 15 | B14: 棋邦-建大 | C14: 24609032
A15: 16 | B15: 正新 | C15: 80603860
A16: 17 | B16: 萬全 | C16: 80594898
A17: 18 | B17: 金宇 | C17: 19200443
A18: 19 | B18: 立城 | C18: 53167470
A19: 20 | B19: 大城 | C19: 47122503
A20: 21 | B20: 歐峰 | C20: 28152695
A21: 22 | B21: 統富 | C21: 17337696
A22: 23 | B22: 欣葆 | C22: 8442337
A23: 24 | B23: 光一 | C23: 49739785
A24: 25 | B24: 光聯 | C24: 49739785
A25: 26 | B25: 聯盛 | C25: 50538343
A26: 27 | B26: 福士 | C26: 23430002
A27: 28 | B27: 澳商環球克林 | C27: 27255005
A28: 29 | B28: 昌樺 | C28: 84810047
A29: 30 | B29: 秀和 | C29: 13160401
A30: 31 | B30: 峰揮 | C30: 未稅
... A75: 76 | B75: 展劭 | C75: -
A76: 77 | B76: 冠宏
A77: 78 | B77: 昇達 | C77: 07660028
A78: 79 | B78: 東禾 | C78: 13874147
A79: 80 | B79: 六友 | C79: 14213047
A80: 81 | B80: 巨輪興 | C80: 未稅
A81: 82 | B81: 統群電機 | C81: 未稅
A82: 83 | B82: 南宏電機 | C82: 未稅
A83: 84 | B83: 施明宏 | C83: 25485620
A84: 85 | B84: 欣承 | C84: 10559052
...

Sheet 工作人員.發票格式.KEY法說明
A1: 黃珮綺 | B1: 三收銀-(三聯式收銀機統一發票) | E1: 刷卡 | G1: 發票可申報營業稅
A2: 胡羽萱 | B2: 三聯式-(手開發票) | E2: 收現
A3: 林祐竹 | B3: 電算機-(電子計算機統一發票) | E3: 匯款 | G3: 營業用商品.店用之耗材皆可申報
B4: 電子發票-(電子發票證明聯) | E4: 支票 | G4: 營業用商品如:輪胎.鋼圈.機器
B5: 退折證明單-(折讓) | G5: 店內用耗材如:廁所清潔劑.店用材料.垃圾袋.文具.公司車輛油單.監視器保全租金.公司車輛維修
B6: 二收銀-(二聯式收銀機統一發票)
B7: 稅費繳納證
G8: 發票不可申報營業稅-認列費用(呈現在年底報表)
G10: 用來體恤員工之費用如:餐費
G11: 老闆一家外出餐費.電器用品.服飾
G13: KEY發票時，照著檔案順序擺放，月份分開放
G14: 一類 | H14: 三聯式-(手開發票) 電算機-(電子計算機統一發票)
G15: 一類 | H15: 電子發票-(電子發票證明聯) 三收銀-(三聯式收銀機統一發票)
G16: 彙總時，類別跟月份要分清楚

Sheet 銷項
A1: 電子 | C1: 中華全佑 | L1: =SUM(L3:L264) -> 863305 | M1: =SUM(M3:M264) -> 822195.24 | N1: =SUM(N3:N264) -> 41108.333 | V1: 電子 | AG1: =SUM(AG3:AG253) -> 0 | AH1: =SUM(AH3:AH253) -> 0 | AI1: =SUM(AI3:AI253) -> 0 | AQ1: 手開 | AS1: 中華全佑三聯式 | BB1: =SUM(BB3:BB251) -> 0 | BC1: =SUM(BC3:BC251) -> 0 | BD1: =SUM(BD3:BD101) -> 0 | BJ1: 手開 | BK1: 中華全佑二聯式 | BP1: =SUM(BP3:BP251) -> 0 | BQ1: =SUM(BQ3:BQ251) -> 0 | BR1: =SUM(BR3:BR251) -> 0
A2: 張數 | B2: 登入日期 | C2: 年月日 | D2: 客編 | E2: 客戶簡稱 | F2: 客戶統編 | G2: 發票號碼 | H2: 品項 | I2: 數量 | J2: 單價 | K2: 小計 | L2: 發票總額 | M2: 未稅金額 | N2: 稅額 | O2: 備註 | P2: 付款方式 | Q2: 信用卡卡號 | R2: 工作人員 | S2: 核對人1 | T2: 核對人2 | U2: 核對人3 | V2: 張數 | W2: 登入日期 | X2: 年月日 | Y2: 客編 | Z2: 客戶簡稱 | AA2: 客戶統編 | AB2: 發票號碼 | AC2: 品項 | AD2: 數量 | AE2: 單價 | AF2: 小計 | AG2: 發票總額 | AH2: 未稅金額 | AI2: 稅額 | AJ2: 備註 | AK2: 付款方式 | AL2: 信用卡卡號 | AM2: 工作人員 | AN2: 核對人1 | AO2: 核對人2 | AP2: 核對人3 | AQ2: 張數 | AR2: 登入日期 | AS2: 年月日 | AT2: 客編 | AU2: 客戶簡稱 | AV2: 客戶統編 | AW2: 發票號碼 | AX2: 品項 | AY2: 數量 | AZ2: 單價 | BA2: 小計 | BB2: 發票總額 | BC2: 未稅金額 | BD2: 稅額 | BE2: 備註 | BF2: 工作人員 | BG2: 核對人1 | BH2: 核對人2 | BI2: 核對人3 | BJ2: 張數 | BK2: 年月日 | BL2: 客編 | BM2: 客戶簡稱 | BN2: 客戶統編 | BO2: 發票號碼 | BP2: 發票總額 | BQ2: 未稅金額 | BR2: 稅額 | BS2: 備註 | BT2: 工作人員 | BU2: 核對人1 | BV2: 核對人2 | BW2: 核對人3
A3: 1 | B3: 1150504 | C3: 1150504 | D3: 629-1 | E3: =VLOOKUP($D3,客戶編輯設定自動代出!$A:$C,3,0) -> 國順龍華 | F3: =VLOOKUP($D3,客戶編輯設定自動代出!$A:$C,2,0) -> 90783671 | G3: ZY23047000 | H3: 輪胎 | I3: 4 | J3: 10000 | K3: =I3*J3 -> 40000 | L3: 40200 | M3: =L3/1.05 -> 38285.714 | N3: 1914 | O3: =IF($K3=$L3,"Y","N") -> N | P3: 匯款 | R3: 黃珮綺 | V3: 1 | Z3: =VLOOKUP($Y3,客戶編輯設定自動代出!$A:$C,3,0) -> #N/A | AA3: =VLOOKUP($Y3,客戶編輯設定自動代出!$A:$C,2,0) -> #N/A | AB3: ZY23047250 | AF3: =AD3*AE3 -> 0 | AH3: =AG3/1.05 -> 0 | AI3: =AH3*0.05 -> 0 | AJ3: =IF($AF3=$AG3,"Y","N") -> Y | AQ3: 1 | AU3: =VLOOKUP($AT3,客戶編輯設定自動代出!$A:$C,3,0) -> #N/A | AV3: =VLOOKUP($AT3,客戶編輯設定自動代出!$A:$C,2,0) -> #N/A | AW3: ZX57093900 | BA3: =AY3*AZ3 -> 0 | BC3: =BB3/1.05 -> 0 | BD3: =BC3*0.05 -> 0 | BE3: =IF($BB3=$BA3,"Y","N") -> Y | BJ3: 1 | BM3: =VLOOKUP(BL3,[1]客戶編輯設定自動代出!L:N,3,0) -> #N/A | BN3: =VLOOKUP(BL3,[1]客戶編輯設定自動代出!L:N,2,0) -> #N/A | BO3: ZZ39642550 | BQ3: =BP3/1.05 -> 0 | BR3: =BQ3*0.05 -> 0
A4: 2 | B4: 1150504 | C4: 1150504 | D4: 629-1 | E4: =VLOOKUP($D4,客戶編輯設定自動代出!$A:$C,3,0) -> 國順龍華 | F4: =VLOOKUP($D4,客戶編輯設定自動代出!$A:$C,2,0) -> 90783671 | G4: ZY23047000 | H4: 工資 | I4: 1 | J4: 200 | P4: 匯款 | R4: 黃珮綺 | V4: 2 | Z4: =VLOOKUP($Y4,客戶編輯設定自動代出!$A:$C,3,0) -> #N/A | AA4: =VLOOKUP($Y4,客戶編輯設定自動代出!$A:$C,2,0) -> #N/A | AB4: ZY23047251 | AF4: =AD4*AE4 -> 0 | AH4: =AG4/1.05 -> 0 | AI4: =AH4*0.05 -> 0 | AJ4: =IF($AF4=$AG4,"Y","N") -> Y | AQ4: 2 | AU4: =VLOOKUP($AT4,客戶編輯設定自動代出!$A:$C,3,0) -> #N/A | AV4: =VLOOKUP($AT4,客戶編輯設定自動代出!$A:$C,2,0) -> #N/A | AW4: ZX57093901 | BA4: =AY4*AZ4 -> 0 | BC4: =BB4/1.05 -> 0 | BD4: =BC4*0.05 -> 0 | BE4: =IF($BB4=$BA4,"Y","N") -> Y | BJ4: 2 | BM4: =VLOOKUP(BL4,[1]客戶編輯設定自動代出!L:N,3,0) -> #N/A | BN4: =VLOOKUP(BL4,[1]客戶編輯設定自動代出!L:N,2,0) -> #N/A | BO4: ZZ39642551 | BQ4: =BP4/1.05 -> 0 | BR4: =BQ4*0.05 -> 0
A5: 3 | B5: 1150504 | C5: 1150504 | D5: 629-1 | E5: =VLOOKUP($D5,客戶編輯設定自動代出!$A:$C,3,0) -> 國順龍華 | F5: =VLOOKUP($D5,客戶編輯設定自動代出!$A:$C,2,0) -> 90783671 | G5: ZY23047001 | H5: 輪胎 | I5: 2 | J5: 12100 | K5: =I5*J5 -> 24200 | L5: 40400 | M5: =L5/1.05 -> 38476.19 | N5: 1924 | O5: =IF($K5=$L5,"Y","N") -> N | P5: 匯款 | R5: 黃珮綺 | V5: 3 | Z5: =VLOOKUP($Y5,客戶編輯設定自動代出!$A:$C,3,0) -> #N/A | AA5: =VLOOKUP($Y5,客戶編輯設定自動代出!$A:$C,2,0) -> #N/A | AB5: ZY23047252 | AF5: =AD5*AE5 -> 0 | AH5: =AG5/1.05 -> 0 | AI5: =AH5*0.05 -> 0 | AJ5: =IF($AF5=$AG5,"Y","N") -> Y | AQ5: 3 | AU5: =VLOOKUP($AT5,客戶編輯設定自動代出!$A:$C,3,0) -> #N/A | AV5: =VLOOKUP($AT5,客戶編輯設定自動代出!$A:$C,2,0) -> #N/A | AW5: ZX57093902 | BA5: =AY5*AZ5 -> 0 | BC5: =BB5/1.05 -> 0 | BD5: =BC5*0.05 -> 0 | BE5: =IF($BB5=$BA5,"Y","N") -> Y | BJ5: 3 | BM5: =VLOOKUP(BL5,[1]客戶編輯設定自動代出!L:N,3,0) -> #N/A | BN5: =VLOOKUP(BL5,[1]客戶編輯設定自動代出!L:N,2,0) -> #N/A | BO5: ZZ39642552 | BQ5: =BP5/1.05 -> 0 | BR5: =BQ5*0.05 -> 0
A6: 4 | B6: 1150504 | C6: 1150504 | D6: 629-1 | E6: =VLOOKUP($D6,客戶編輯設定自動代出!$A:$C,3,0) -> 國順龍華 | F6: =VLOOKUP($D6,客戶編輯設定自動代出!$A:$C,2,0) -> 90783671 | G6: ZY23047001 | H6: 輪胎 | I6: 2 | J6: 8100 | P6: 匯款 | R6: 黃珮綺 | V6: 4 | Z6: =VLOOKUP($Y6,客戶編輯設定自動代出!$A:$C,3,0) -> #N/A | AA6: =VLOOKUP($Y6,客戶編輯設定自動代出!$A:$C,2,0) -> #N/A | AB6: ZY23047253 | AF6: =AD6*AE6 -> 0 | AH6: =AG6/1.05 -> 0 | AI6: =AH6*0.05 -> 0 | AJ6: =IF($AF6=$AG6,"Y","N") -> Y | AQ6: 4 | AU6: =VLOOKUP($AT6,客戶編輯設定自動代出!$A:$C,3,0) -> #N/A | AV6: =VLOOKUP($AT6,客戶編輯設定自動代出!$A:$C,2,0) -> #N/A | AW6: ZX57093903 | BA6: =AY6*AZ6 -> 0 | BC6: =BB6/1.05 -> 0 | BD6: =BC6*0.05 -> 0 | BE6: =IF($BB6=$BA6,"Y","N") -> Y | BJ6: 4 | BM6: =VLOOKUP(BL6,[1]客戶編輯設定自動代出!L:N,3,0) -> #N/A | BN6: =VLOOKUP(BL6,[1]客戶編輯設定自動代出!L:N,2,0) -> #N/A | BO6: ZZ39642553 | BQ6: =BP6/1.05 -> 0 | BR6: =BQ6*0.05 -> 0
A7: 5 | B7: 1150504 | C7: 1150504 | D7: 629-1 | E7: =VLOOKUP($D7,客戶編輯設定自動代出!$A:$C,3,0) -> 國順龍華 | F7: =VLOOKUP($D7,客戶編輯設定自動代出!$A:$C,2,0) -> 90783671 | G7: ZY23047002 | H7: 鋼圈 | I7: 1 | J7: 5250 | K7: =I7*J7 -> 5250 | L7: 6930 | M7: =L7/1.05 -> 6600 | N7: =M7*0.05 -> 330 | O7: =IF($K7=$L7,"Y","N") -> N | P7: 匯款 | R7: 黃珮綺 | V7: 5 | Z7: =VLOOKUP($Y7,客戶編輯設定自動代出!$A:$C,3,0) -> #N/A | AA7: =VLOOKUP($Y7,客戶編輯設定自動代出!$A:$C,2,0) -> #N/A | AB7: ZY23047254 | AF7: =AD7*AE7 -> 0 | AH7: =AG7/1.05 -> 0 | AI7: =AH7*0.05 -> 0 | AJ7: =IF($AF7=$AG7,"Y","N") -> Y | AQ7: 5 | AU7: =VLOOKUP($AT7,客戶編輯設定自動代出!$A:$C,3,0) -> #N/A | AV7: =VLOOKUP($AT7,客戶編輯設定自動代出!$A:$C,2,0) -> #N/A | AW7: ZX57093904 | BA7: =AY7*AZ7 -> 0 | BC7: =BB7/1.05 -> 0 | BD7: =BC7*0.05 -> 0 | BE7: =IF($BB7=$BA7,"Y","N") -> Y | BJ7: 5 | BM7: =VLOOKUP(BL7,[1]客戶編輯設定自動代出!L:N,3,0) -> #N/A | BN7: =VLOOKUP(BL7,[1]客戶編輯設定自動代出!L:N,2,0) -> #N/A | BO7: ZZ39642554 | BQ7: =BP7/1.05 -> 0 | BR7: =BQ7*0.05 -> 0
A8: 6 | B8: 1150504 | C8: 1150504 | D8: 629-1 | E8: =VLOOKUP($D8,客戶編輯設定自動代出!$A:$C,3,0) -> 國順龍華 | F8: =VLOOKUP($D8,客戶編輯設定自動代出!$A:$C,2,0) -> 90783671 | G8: ZY23047002 | H8: 工資 | I8: 1 | J8: 1050 | P8: 匯款 | R8: 黃珮綺 | V8: 6 | Z8: =VLOOKUP($Y8,客戶編輯設定自動代出!$A:$C,3,0) -> #N/A | AA8: =VLOOKUP($Y8,客戶編輯設定自動代出!$A:$C,2,0) -> #N/A | AB8: ZY23047255 | AF8: =AD8*AE8 -> 0 | AH8: =AG8/1.05 -> 0 | AI8: =AH8*0.05 -> 0 | AJ8: =IF($AF8=$AG8,"Y","N") -> Y | AQ8: 6 | AU8: =VLOOKUP($AT8,客戶編輯設定自動代出!$A:$C,3,0) -> #N/A | AV8: =VLOOKUP($AT8,客戶編輯設定自動代出!$A:$C,2,0) -> #N/A | AW8: ZX57093905 | BA8: =AY8*AZ8 -> 0 | BC8: =BB8/1.05 -> 0 | BD8: =BC8*0.05 -> 0 | BE8: =IF($BB8=$BA8,"Y","N") -> Y | BJ8: 6 | BM8: =VLOOKUP(BL8,[1]客戶編輯設定自動代出!L:N,3,0) -> #N/A | BN8: =VLOOKUP(BL8,[1]客戶編輯設定自動代出!L:N,2,0) -> #N/A | BO8: ZZ39642555 | BQ8: =BP8/1.05 -> 0 | BR8: =BQ8*0.05 -> 0
A9: 7 | B9: 1150504 | C9: 1150504 | D9: 629-1 | E9: =VLOOKUP($D9,客戶編輯設定自動代出!$A:$C,3,0) -> 國順龍華 | F9: =VLOOKUP($D9,客戶編輯設定自動代出!$A:$C,2,0) -> 90783671 | G9: ZY23047002 | H9: 工資 | I9: 1 | J9: 630 | P9: 匯款 | R9: 黃珮綺 | V9: 7 | Z9: =VLOOKUP($Y9,客戶編輯設定自動代出!$A:$C,3,0) -> #N/A | AA9: =VLOOKUP($Y9,客戶編輯設定自動代出!$A:$C,2,0) -> #N/A | AB9: ZY23047256 | AF9: =AD9*AE9 -> 0 | AH9: =AG9/1.05 -> 0 | AI9: =AH9*0.05 -> 0 | AJ9: =IF($AF9=$AG9,"Y","N") -> Y | AQ9: 7 | AU9: =VLOOKUP($AT9,客戶編輯設定自動代出!$A:$C,3,0) -> #N/A | AV9: =VLOOKUP($AT9,客戶編輯設定自動代出!$A:$C,2,0) -> #N/A | AW9: ZX57093906 | BA9: =AY9*AZ9 -> 0 | BC9: =BB9/1.05 -> 0 | BD9: =BC9*0.05 -> 0 | BE9: =IF($BB9=$BA9,"Y","N") -> Y | BJ9: 7 | BM9: =VLOOKUP(BL9,[1]客戶編輯設定自動代出!L:N,3,0) -> #N/A | BN9: =VLOOKUP(BL9,[1]客戶編輯設定自動代出!L:N,2,0) -> #N/A | BO9: ZZ39642556 | BQ9: =BP9/1.05 -> 0 | BR9: =BQ9*0.05 -> 0
A10: 8 | B10: 1150504 | C10: 1150504 | D10: 629-1 | E10: =VLOOKUP($D10,客戶編輯設定自動代出!$A:$C,3,0) -> 國順龍華 | F10: =VLOOKUP($D10,客戶編輯設定自動代出!$A:$C,2,0) -> 90783671 | G10: ZY23047003 | H10: 輪胎 | I10: 2 | J10: 8100 | K10: =I10*J10 -> 16200 | L10: 16200 | M10: =L10/1.05 -> 15428.571 | N10: 771 | O10: =IF($K10=$L10,"Y","N") -> Y | P10: 匯款 | R10: 黃珮綺 | V10: 8 | Z10: =VLOOKUP($Y10,客戶編輯設定自動代出!$A:$C,3,0) -> #N/A | AA10: =VLOOKUP($Y10,客戶編輯設定自動代出!$A:$C,2,0) -> #N/A | AB10: ZY23047257 | AF10: =AD10*AE10 -> 0 | AH10: =AG10/1.05 -> 0 | AI10: =AH10*0.05 -> 0 | AJ10: =IF($AF10=$AG10,"Y","N") -> Y | AQ10: 8 | AU10: =VLOOKUP($AT10,客戶編輯設定自動代出!$A:$C,3,0) -> #N/A | AV10: =VLOOKUP($AT10,客戶編輯設定自動代出!$A:$C,2,0) -> #N/A | AW10: ZX57093907 | BA10: =AY10*AZ10 -> 0 | BC10: =BB10/1.05 -> 0 | BD10: =BC10*0.05 -> 0 | BE10: =IF($BB10=$BA10,"Y","N") -> Y | BJ10: 8 | BM10: =VLOOKUP(BL10,[1]客戶編輯設定自動代出!L:N,3,0) -> #N/A | BN10: =VLOOKUP(BL10,[1]客戶編輯設定自動代出!L:N,2,0) -> #N/A | BO10: ZZ39642557 | BQ10: =BP10/1.05 -> 0 | BR10: =BQ10*0.05 -> 0
A11: 9 | B11: 1150504 | C11: 1150504 | D11: 629-1 | E11: =VLOOKUP($D11,客戶編輯設定自動代出!$A:$C,3,0) -> 國順龍華 | F11: =VLOOKUP($D11,客戶編輯設定自動代出!$A:$C,2,0) -> 90783671 | G11: ZY23047004 | H11: 輪胎 | I11: 4 | J11: 10000 | K11: =I11*J11 -> 40000 | L11: 40600 | M11: =L11/1.05 -> 38666.667 | N11: =M11*0.05 -> 1933.3333 | O11: =IF($K11=$L11,"Y","N") -> N | P11: 匯款 | R11: 黃珮綺 | V11: 9 | Z11: =VLOOKUP($Y11,客戶編輯設定自動代出!$A:$C,3,0) -> #N/A | AA11: =VLOOKUP($Y11,客戶編輯設定自動代出!$A:$C,2,0) -> #N/A | AB11: ZY23047258 | AF11: =AD11*AE11 -> 0 | AH11: =AG11/1.05 -> 0 | AI11: =AH11*0.05 -> 0 | AJ11: =IF($AF11=$AG11,"Y","N") -> Y | AQ11: 9 | AU11: =VLOOKUP($AT11,客戶編輯設定自動代出!$A:$C,3,0) -> #N/A | AV11: =VLOOKUP($AT11,客戶編輯設定自動代出!$A:$C,2,0) -> #N/A | AW11: ZX57093908 | BA11: =AY11*AZ11 -> 0 | BC11: =BB11/1.05 -> 0 | BD11: =BC11*0.05 -> 0 | BE11: =IF($BB11=$BA11,"Y","N") -> Y | BJ11: 9 | BM11: =VLOOKUP(BL11,[1]客戶編輯設定自動代出!L:N,3,0) -> #N/A | BN11: =VLOOKUP(BL11,[1]客戶編輯設定自動代出!L:N,2,0) -> #N/A | BO11: ZZ39642558 | BQ11: =BP11/1.05 -> 0 | BR11: =BQ11*0.05 -> 0
A12: 10 | B12: 1150504 | C12: 1150504 | D12: 629-1 | E12: =VLOOKUP($D12,客戶編輯設定自動代出!$A:$C,3,0) -> 國順龍華 | F12: =VLOOKUP($D12,客戶編輯設定自動代出!$A:$C,2,0) -> 90783671 | G12: ZY23047004 | H12: 工資 | I12: 1 | J12: 600 | P12: 匯款 | R12: 黃珮綺 | V12: 10 | Z12: =VLOOKUP($Y12,客戶編輯設定自動代出!$A:$C,3,0) -> #N/A | AA12: =VLOOKUP($Y12,客戶編輯設定自動代出!$A:$C,2,0) -> #N/A | AB12: ZY23047259 | AF12: =AD12*AE12 -> 0 | AH12: =AG12/1.05 -> 0 | AI12: =AH12*0.05 -> 0 | AJ12: =IF($AF12=$AG12,"Y","N") -> Y | AQ12: 10 | AU12: =VLOOKUP($AT12,客戶編輯設定自動代出!$A:$C,3,0) -> #N/A | AV12: =VLOOKUP($AT12,客戶編輯設定自動代出!$A:$C,2,0) -> #N/A | AW12: ZX57093909 | BA12: =AY12*AZ12 -> 0 | BC12: =BB12/1.05 -> 0 | BD12: =BC12*0.05 -> 0 | BE12: =IF($BB12=$BA12,"Y","N") -> Y | BJ12: 10 | BM12: =VLOOKUP(BL12,[1]客戶編輯設定自動代出!L:N,3,0) -> #N/A | BN12: =VLOOKUP(BL12,[1]客戶編輯設定自動代出!L:N,2,0) -> #N/A | BO12: ZZ39642559 | BQ12: =BP12/1.05 -> 0 | BR12: =BQ12*0.05 -> 0
A13: 11 | B13: 1150504 | C13: 1150504 | D13: 8 | E13: =VLOOKUP($D13,客戶編輯設定自動代出!$A:$C,3,0) -> 路人 | F13: =VLOOKUP($D13,客戶編輯設定自動代出!$A:$C,2,0) -> 0 | G13: ZY23047005 | H13: 輪胎 | I13: 1 | J13: 10000 | K13: =I13*J13 -> 10000 | L13: 10500 | M13: =L13/1.05 -> 10000 | N13: 500 | O13: =IF($K13=$L13,"Y","N") -> N | P13: 匯款 | R13: 林祐竹 | V13: 11 | Z13: =VLOOKUP($Y13,客戶編輯設定自動代出!$A:$C,3,0) -> #N/A | AA13: =VLOOKUP($Y13,客戶編輯設定自動代出!$A:$C,2,0) -> #N/A | AB13: ZY23047260 | AF13: =AD13*AE13 -> 0 | AH13: =AG13/1.05 -> 0 | AI13: =AH13*0.05 -> 0 | AJ13: =IF($AF13=$AG13,"Y","N") -> Y | AQ13: 11 | AU13: =VLOOKUP($AT13,客戶編輯設定自動代出!$A:$C,3,0) -> #N/A | AV13: =VLOOKUP($AT13,客戶編輯設定自動代出!$A:$C,2,0) -> #N/A | AW13: ZX57093910 | BA13: =AY13*AZ13 -> 0 | BC13: =BB13/1.05 -> 0 | BD13: =BC13*0.05 -> 0 | BE13: =IF($BB13=$BA13,"Y","N") -> Y | BJ13: 11 | BM13: =VLOOKUP(BL13,[1]客戶編輯設定自動代出!L:N,3,0) -> #N/A | BN13: =VLOOKUP(BL13,[1]客戶編輯設定自動代出!L:N,2,0) -> #N/A | BO13: ZZ39642560 | BQ13: =BP13/1.05 -> 0 | BR13: =BQ13*0.05 -> 0
A14: 12 | B14: 1150504 | C14: 1150504 | D14: 8 | E14: =VLOOKUP($D14,客戶編輯設定自動代出!$A:$C,3,0) -> 路人 | F14: =VLOOKUP($D14,客戶編輯設定自動代出!$A:$C,2,0) -> 0 | G14: ZY23047006 | H14: 輪胎 | I14: 1 | J14: 10000 | K14: =I14*J14 -> 10000 | L14: 10500 | M14: =L14/1.05 -> 10000 | N14: 500 | O14: =IF($K14=$L14,"Y","N") -> N | P14: 匯款 | R14: 林祐竹 | V14: 12 | Z14: =VLOOKUP($Y14,客戶編輯設定自動代出!$A:$C,3,0) -> #N/A | AA14: =VLOOKUP($Y14,客戶編輯設定自動代出!$A:$C,2,0) -> #N/A | AB14: ZY23047261 | AF14: =AD14*AE14 -> 0 | AH14: =AG14/1.05 -> 0 | AI14: =AH14*0.05 -> 0 | AJ14: =IF($AF14=$AG14,"Y","N") -> Y | AQ14: 12 | AU14: =VLOOKUP($AT14,客戶編輯設定自動代出!$A:$C,3,0) -> #N/A | AV14: =VLOOKUP($AT14,客戶編輯設定自動代出!$A:$C,2,0) -> #N/A | AW14: ZX57093911 | BA14: =AY14*AZ14 -> 0 | BC14: =BB14/1.05 -> 0 | BD14: =BC14*0.05 -> 0 | BE14: =IF($BB14=$BA14,"Y","N") -> Y | BJ14: 12 | BM14: =VLOOKUP(BL14,[1]客戶編輯設定自動代出!L:N,3,0) -> #N/A | BN14: =VLOOKUP(BL14,[1]客戶編輯設定自動代出!L:N,2,0) -> #N/A | BO14: ZZ39642561 | BQ14: =BP14/1.05 -> 0 | BR14: =BQ14*0.05 -> 0
A15: 13 | B15: 1150504 | C15: 1150504 | D15: 838 | E15: =VLOOKUP($D15,客戶編輯設定自動代出!$A:$C,3,0) -> 嘉盛汽車 | F15: 66813653 | G15: ZY23047007 | O15: 作廢 | R15: 林祐竹 | V15: 13 | Z15: =VLOOKUP($Y15,客戶編輯設定自動代出!$A:$C,3,0) -> #N/A | AA15: =VLOOKUP($Y15,客戶編輯設定自動代出!$A:$C,2,0) -> #N/A | AB15: ZY23047262 | AF15: =AD15*AE15 -> 0 | AH15: =AG15/1.05 -> 0 | AI15: =AH15*0.05 -> 0 | AJ15: =IF($AF15=$AG15,"Y","N") -> Y | AQ15: 13 | AU15: =VLOOKUP($AT15,客戶編輯設定自動代出!$A:$C,3,0) -> #N/A | AV15: =VLOOKUP($AT15,客戶編輯設定自動代出!$A:$C,2,0) -> #N/A | AW15: ZX57093912 | BA15: =AY15*AZ15 -> 0 | BC15: =BB15/1.05 -> 0 | BD15: =BC15*0.05 -> 0 | BE15: =IF($BB15=$BA15,"Y","N") -> Y | BJ15: 13 | BM15: =VLOOKUP(BL15,[1]客戶編輯設定自動代出!L:N,3,0) -> #N/A | BN15: =VLOOKUP(BL15,[1]客戶編輯設定自動代出!L:N,2,0) -> #N/A | BO15: ZZ39642562 | BQ15: =BP15/1.05 -> 0 | BR15: =BQ15*0.05 -> 0
A16: 14 | B16: 1150504 | C16: 1150504 | D16: 838 | E16: =VLOOKUP($D16,客戶編輯設定自動代出!$A:$C,3,0) -> 嘉盛汽車 | F16: =VLOOKUP($D16,客戶編輯設定自動代出!$A:$C,2,0) -> 49389534 | G16: ZY23047008 | O16: 作廢 | R16: 林祐竹 | V16: 14 | Z16: =VLOOKUP($Y16,客戶編輯設定自動代出!$A:$C,3,0) -> #N/A | AA16: =VLOOKUP($Y16,客戶編輯設定自動代出!$A:$C,2,0) -> #N/A | AB16: ZY23047263 | AF16: =AD16*AE16 -> 0 | AH16: =AG16/1.05 -> 0 | AI16: =AH16*0.05 -> 0 | AJ16: =IF($AF16=$AG16,"Y","N") -> Y | AQ16: 14 | AU16: =VLOOKUP($AT16,客戶編輯設定自動代出!$A:$C,3,0) -> #N/A | AV16: =VLOOKUP($AT16,客戶編輯設定自動代出!$A:$C,2,0) -> #N/A | AW16: ZX57093913 | BA16: =AY16*AZ16 -> 0 | BC16: =BB16/1.05 -> 0 | BD16: =BC16*0.05 -> 0 | BE16: =IF($BB16=$BA16,"Y","N") -> Y | BJ16: 14 | BM16: =VLOOKUP(BL16,[1]客戶編輯設定自動代出!L:N,3,0) -> #N/A | BN16: =VLOOKUP(BL16,[1]客戶編輯設定自動代出!L:N,2,0) -> #N/A | BO16: ZZ39642563 | BQ16: =BP16/1.05 -> 0 | BR16: =BQ16*0.05 -> 0
A17: 15 | B17: 1150504 | C17: 1150504 | D17: 8 | E17: =VLOOKUP($D17,客戶編輯設定自動代出!$A:$C,3,0) -> 路人 | F17: 28557210 | G17: ZY23047009 | H17: 輪胎 | I17: 2 | J17: 5800 | K17: =I17*J17 -> 11600 | L17: 12180 | M17: =L17/1.05 -> 11600 | N17: 580 | O17: =IF($K17=$L17,"Y","N") -> N | P17: 刷卡 | Q17: 5589360091090288 | R17: 林祐竹 | V17: 15 | Z17: =VLOOKUP($Y17,客戶編輯設定自動代出!$A:$C,3,0) -> #N/A | AA17: =VLOOKUP($Y17,客戶編輯設定自動代出!$A:$C,2,0) -> #N/A | AB17: ZY23047264 | AF17: =AD17*AE17 -> 0 | AH17: =AG17/1.05 -> 0 | AI17: =AH17*0.05 -> 0 | AJ17: =IF($AF17=$AG17,"Y","N") -> Y | AQ17: 15 | AU17: =VLOOKUP($AT17,客戶編輯設定自動代出!$A:$C,3,0) -> #N/A | AV17: =VLOOKUP($AT17,客戶編輯設定自動代出!$A:$C,2,0) -> #N/A | AW17: ZX57093914 | BA17: =AY17*AZ17 -> 0 | BC17: =BB17/1.05 -> 0 | BD17: =BC17*0.05 -> 0 | BE17: =IF($BB17=$BA17,"Y","N") -> Y | BJ17: 15 | BM17: =VLOOKUP(BL17,[1]客戶編輯設定自動代出!L:N,3,0) -> #N/A | BN17: =VLOOKUP(BL17,[1]客戶編輯設定自動代出!L:N,2,0) -> #N/A | BO17: ZZ39642564 | BQ17: =BP17/1.05 -> 0 | BR17: =BQ17*0.05 -> 0
A18: 16 | B18: 1150507 | C18: 1150507 | D18: 295 | E18: =VLOOKUP($D18,客戶編輯設定自動代出!$A:$C,3,0) -> 光復中學 | F18: =VLOOKUP($D18,客戶編輯設定自動代出!$A:$C,2,0) -> 46802405 | G18: ZY23047010 | H18: 工資 | I18: 2 | J18: 600 | K18: =I18*J18 -> 1200 | L18: 1200 | M18: =L18/1.05 -> 1142.8571 | N18: 57 | O18: =IF($K18=$L18,"Y","N") -> Y | P18: 匯款 | R18: 林祐竹 | V18: 16 | Z18: =VLOOKUP($Y18,客戶編輯設定自動代出!$A:$C,3,0) -> #N/A | AA18: =VLOOKUP($Y18,客戶編輯設定自動代出!$A:$C,2,0) -> #N/A | AB18: ZY23047265 | AF18: =AD18*AE18 -> 0 | AH18: =AG18/1.05 -> 0 | AI18: =AH18*0.05 -> 0 | AJ18: =IF($AF18=$AG18,"Y","N") -> Y | AQ18: 16 | AU18: =VLOOKUP($AT18,客戶編輯設定自動代出!$A:$C,3,0) -> #N/A | AV18: =VLOOKUP($AT18,客戶編輯設定自動代出!$A:$C,2,0) -> #N/A | AW18: ZX57093915 | BA18: =AY18*AZ18 -> 0 | BC18: =BB18/1.05 -> 0 | BD18: =BC18*0.05 -> 0 | BE18: =IF($BB18=$BA18,"Y","N") -> Y | BJ18: 16 | BM18: =VLOOKUP(BL18,[1]客戶編輯設定自動代出!L:N,3,0) -> #N/A | BN18: =VLOOKUP(BL18,[1]客戶編輯設定自動代出!L:N,2,0) -> #N/A | BO18: ZZ39642565 | BQ18: =BP18/1.05 -> 0 | BR18: =BQ18*0.05 -> 0
A19: 17 | B19: 1150507 | C19: 1150507 | D19: 416 | E19: =VLOOKUP($D19,客戶編輯設定自動代出!$A:$C,3,0) -> 竹南鎮公所 | F19: =VLOOKUP($D19,客戶編輯設定自動代出!$A:$C,2,0) -> 50400804 | G19: ZY23047011 | H19: 輪胎 | I19: 5 | J19: 5662 | K19: =I19*J19 -> 28310 | L19: 28310 | M19: =L19/1.05 -> 26961.905 | N19: 1348 | O19: =IF($K19=$L19,"Y","N") -> Y | P19: 匯款 | R19: 林祐竹 | V19: 17 | Z19: =VLOOKUP($Y19,客戶編輯設定自動代出!$A:$C,3,0) -> #N/A | AA19: =VLOOKUP($Y19,客戶編輯設定自動代出!$A:$C,2,0) -> #N/A | AB19: ZY23047266 | AF19: =AD19*AE19 -> 0 | AH19: =AG19/1.05 -> 0 | AI19: =AH19*0.05 -> 0 | AJ19: =IF($AF19=$AG19,"Y","N") -> Y | AQ19: 17 | AU19: =VLOOKUP($AT19,客戶編輯設定自動代出!$A:$C,3,0) -> #N/A | AV19: =VLOOKUP($AT19,客戶編輯設定自動代出!$A:$C,2,0) -> #N/A | AW19: ZX57093916 | BA19: =AY19*AZ19 -> 0 | BC19: =BB19/1.05 -> 0 | BD19: =BC19*0.05 -> 0 | BE19: =IF($BB19=$BA19,"Y","N") -> Y | BJ19: 17 | BM19: =VLOOKUP(BL19,[1]客戶編輯設定自動代出!L:N,3,0) -> #N/A | BN19: =VLOOKUP(BL19,[1]客戶編輯設定自動代出!L:N,2,0) -> #N/A | BO19: ZZ39642566 | BQ19: =BP19/1.05 -> 0 | BR19: =BQ19*0.05 -> 0
A20: 18 | B20: 1150509 | C20: 1150509 | D20: 702 | E20: =VLOOKUP($D20,客戶編輯設定自動代出!$A:$C,3,0) -> 交通大學 | F20: 87557573 | G20: ZY23047012 | H20: 輪胎 | I20: 4 | J20: 16000 | K20: =I20*J20 -> 64000 | L20: 67200 | M20: =L20/1.05 -> 64000 | N20: 3200 | O20: =IF($K20=$L20,"Y","N") -> N | P20: 匯款 | R20: 林祐竹 | V20: 18 | Z20: =VLOOKUP($Y20,客戶編輯設定自動代出!$A:$C,3,0) -> #N/A | AA20: =VLOOKUP($Y20,客戶編輯設定自動代出!$A:$C,2,0) -> #N/A | AB20: ZY23047267 | AF20: =AD20*AE20 -> 0 | AH20: =AG20/1.05 -> 0 | AI20: =AH20*0.05 -> 0 | AJ20: =IF($AF20=$AG20,"Y","N") -> Y | AQ20: 18 | AU20: =VLOOKUP($AT20,客戶編輯設定自動代出!$A:$C,3,0) -> #N/A | AV20: =VLOOKUP($AT20,客戶編輯設定自動代出!$A:$C,2,0) -> #N/A | AW20: ZX57093917 | BA20: =AY20*AZ20 -> 0 | BC20: =BB20/1.05 -> 0 | BD20: =BC20*0.05 -> 0 | BE20: =IF($BB20=$BA20,"Y","N") -> Y | BJ20: 18 | BM20: =VLOOKUP(BL20,[1]客戶編輯設定自動代出!L:N,3,0) -> #N/A | BN20: =VLOOKUP(BL20,[1]客戶編輯設定自動代出!L:N,2,0) -> #N/A | BO20: ZZ39642567 | BQ20: =BP20/1.05 -> 0 | BR20: =BQ20*0.05 -> 0
A21: 19 | B21: 1150509 | C21: 1150509 | D21: 8 | E21: =VLOOKUP($D21,客戶編輯設定自動代出!$A:$C,3,0) -> 路人 | F21: 90584954 | G21: ZY23047013 | H21: 輪胎定位 | I21: 1 | J21: 2000 | K21: =I21*J21 -> 2000 | L21: 2100 | M21: =L21/1.05 -> 2000 | N21: 100 | O21: =IF($K21=$L21,"Y","N") -> N | P21: 收現 | R21: 林祐竹 | V21: 19 | Z21: =VLOOKUP($Y21,客戶編輯設定自動代出!$A:$C,3,0) -> #N/A | AA21: =VLOOKUP($Y21,客戶編輯設定自動代出!$A:$C,2,0) -> #N/A | AB21: ZY23047267 | AF21: =AD21*AE21 -> 0 | AH21: =AG21/1.05 -> 0 | AI21: =AH21*0.05 -> 0 | AJ21: =IF($AF21=$AG21,"Y","N") -> Y | AQ21: 19 | AU21: =VLOOKUP($AT21,客戶編輯設定自動代出!$A:$C,3,0) -> #N/A | AV21: =VLOOKUP($AT21,客戶編輯設定自動代出!$A:$C,2,0) -> #N/A | AW21: ZX57093918 | BA21: =AY21*AZ21 -> 0 | BC21: =BB21/1.05 -> 0 | BD21: =BC21*0.05 -> 0 | BE21: =IF($BB21=$BA21,"Y","N") -> Y | BJ21: 19 | BM21: =VLOOKUP(BL21,[1]客戶編輯設定自動代出!L:N,3,0) -> #N/A | BN21: =VLOOKUP(BL21,[1]客戶編輯設定自動代出!L:N,2,0) -> #N/A | BO21: ZZ39642568 | BQ21: =BP21/1.05 -> 0 | BR21: =BQ21*0.05 -> 0
A22: 20 | B22: 1150509 | C22: 1150509 | D22: 932 | E22: =VLOOKUP($D22,客戶編輯設定自動代出!$A:$C,3,0) -> 加和紙業 | F22: =VLOOKUP($D22,客戶編輯設定自動代出!$A:$C,2,0) -> 50547286 | G22: ZY23047014 | H22: 補胎 | I22: 1 | J22: 400 | K22: =I22*J22 -> 400 | L22: 400 | M22: =L22/1.05 -> 380.95238 | N22: 19 | O22: =IF($K22=$L22,"Y","N") -> Y | P22: 匯款 | R22: 林祐竹 | V22: 20 | Z22: =VLOOKUP($Y22,客戶編輯設定自動代出!$A:$C,3,0) -> #N/A | AA22: =VLOOKUP($Y22,客戶編輯設定自動代出!$A:$C,2,0) -> #N/A | AB22: ZY23047268 | AF22: =AD22*AE22 -> 0 | AH22: =AG22/1.05 -> 0 | AI22: =AH22*0.05 -> 0 | AJ22: =IF($AF22=$AG22,"Y","N") -> Y | AQ22: 20 | AU22: =VLOOKUP($AT22,客戶編輯設定自動代出!$A:$C,3,0) -> #N/A | AV22: =VLOOKUP($AT22,客戶編輯設定自動代出!$A:$C,2,0) -> #N/A | AW22: ZX57093919 | BA22: =AY22*AZ22 -> 0 | BC22: =BB22/1.05 -> 0 | BD22: =BC22*0.05 -> 0 | BE22: =IF($BB22=$BA22,"Y","N") -> Y | BJ22: 20 | BM22: =VLOOKUP(BL22,[1]客戶編輯設定自動代出!L:N,3,0) -> #N/A | BN22: =VLOOKUP(BL22,[1]客戶編輯設定自動代出!L:N,2,0) -> #N/A | BO22: ZZ39642569 | BQ22: =BP22/1.05 -> 0 | BR22: =BQ22*0.05 -> 0
A23: 21 | B23: 1150509 | C23: 1150509 | D23: 932 | E23: =VLOOKUP($D23,客戶編輯設定自動代出!$A:$C,3,0) -> 加和紙業 | F23: =VLOOKUP($D23,客戶編輯設定自動代出!$A:$C,2,0) -> 50547286 | G23: ZY23047015 | H23: 輪胎 | I23: 2 | J23: 7000 | K23: =I23*J23 -> 14000 | L23: 14000 | M23: =L23/1.05 -> 13333.333 | N23: 667 | O23: =IF($K23=$L23,"Y","N") -> Y | P23: 匯款 | R23: 林祐竹 | V23: 21 | Z23: =VLOOKUP($Y23,客戶編輯設定自動代出!$A:$C,3,0) -> #N/A | AA23: =VLOOKUP($Y23,客戶編輯設定自動代出!$A:$C,2,0) -> #N/A | AB23: ZY23047269 | AF23: =AD23*AE23 -> 0 | AH23: =AG23/1.05 -> 0 | AI23: =AH23*0.05 -> 0 | AJ23: =IF($AF23=$AG23,"Y","N") -> Y | AQ23: 21 | AU23: =VLOOKUP($AT23,客戶編輯設定自動代出!$A:$C,3,0) -> #N/A | AV23: =VLOOKUP($AT23,客戶編輯設定自動代出!$A:$C,2,0) -> #N/A | AW23: ZX57093920 | BA23: =AY23*AZ23 -> 0 | BC23: =BB23/1.05 -> 0 | BD23: =BC23*0.05 -> 0 | BE23: =IF($BB23=$BA23,"Y","N") -> Y | BJ23: 21 | BM23: =VLOOKUP(BL23,[1]客戶編輯設定自動代出!L:N,3,0) -> #N/A | BN23: =VLOOKUP(BL23,[1]客戶編輯設定自動代出!L:N,2,0) -> #N/A | BO23: ZZ39642570 | BQ23: =BP23/1.05 -> 0 | BR23: =BQ23*0.05 -> 0
A24: 22 | B24: 1150509 | C24: 1150509 | D24: 8 | E24: =VLOOKUP($D24,客戶編輯設定自動代出!$A:$C,3,0) -> 路人 | F24: =VLOOKUP($D24,客戶編輯設定自動代出!$A:$C,2,0) -> 0 | G24: ZY23047016 | H24: 輪胎 | I24: 4 | J24: 5500 | K24: =I24*J24 -> 22000 | L24: 23100 | M24: =L24/1.05 -> 22000 | N24: 1100 | O24: =IF($K24=$L24,"Y","N") -> N | P24: 刷卡 | Q24: 4002118412475907 | R24: 林祐竹 | V24: 22 | Z24: =VLOOKUP($Y24,客戶編輯設定自動代出!$A:$C,3,0) -> #N/A | AA24: =VLOOKUP($Y24,客戶編輯設定自動代出!$A:$C,2,0) -> #N/A | AB24: ZY23047270 | AF24: =AD24*AE24 -> 0 | AH24: =AG24/1.05 -> 0 | AI24: =AH24*0.05 -> 0 | AJ24: =IF($AF24=$AG24,"Y","N") -> Y | AQ24: 22 | AU24: =VLOOKUP($AT24,客戶編輯設定自動代出!$A:$C,3,0) -> #N/A | AV24: =VLOOKUP($AT24,客戶編輯設定自動代出!$A:$C,2,0) -> #N/A | AW24: ZX57093921 | BA24: =AY24*AZ24 -> 0 | BC24: =BB24/1.05 -> 0 | BD24: =BC24*0.05 -> 0 | BE24: =IF($BB24=$BA24,"Y","N") -> Y | BJ24: 22 | BM24: =VLOOKUP(BL24,[1]客戶編輯設定自動代出!L:N,3,0) -> #N/A | BN24: =VLOOKUP(BL24,[1]客戶編輯設定自動代出!L:N,2,0) -> #N/A | BO24: ZZ39642571 | BQ24: =BP24/1.05 -> 0 | BR24: =BQ24*0.05 -> 0
A25: 23 | B25: 1150511 | C25: 1150511 | D25: 8 | E25: =VLOOKUP($D25,客戶編輯設定自動代出!$A:$C,3,0) -> 路人 | F25: 95487333 | G25: ZY23047017 | H25: 輪胎 | I25: 2 | J25: 12000 | K25: =I25*J25 -> 24000 | L25: 25200 | M25: =L25/1.05 -> 24000 | N25: 1200 | O25: =IF($K25=$L25,"Y","N") -> N | P25: 匯款 | R25: 林祐竹 | V25: 23 | Z25: =VLOOKUP($Y25,客戶編輯設定自動代出!$A:$C,3,0) -> #N/A | AA25: =VLOOKUP($Y25,客戶編輯設定自動代出!$A:$C,2,0) -> #N/A | AB25: ZY23047271 | AF25: =AD25*AE25 -> 0 | AH25: =AG25/1.05 -> 0 | AI25: =AH25*0.05 -> 0 | AJ25: =IF($AF25=$AG25,"Y","N") -> Y | AQ25: 23 | AU25: =VLOOKUP($AT25,客戶編輯設定自動代出!$A:$C,3,0) -> #N/A | AV25: =VLOOKUP($AT25,客戶編輯設定自動代出!$A:$C,2,0) -> #N/A | AW25: ZX57093922 | BA25: =AY25*AZ25 -> 0 | BC25: =BB25/1.05 -> 0 | BD25: =BC25*0.05 -> 0 | BE25: =IF($BB25=$BA25,"Y","N") -> Y | BJ25: 23 | BM25: =VLOOKUP(BL25,[1]客戶編輯設定自動代出!L:N,3,0) -> #N/A | BN25: =VLOOKUP(BL25,[1]客戶編輯設定自動代出!L:N,2,0) -> #N/A | BO25: ZZ39642572 | BQ25: =BP25/1.05 -> 0 | BR25: =BQ25*0.05 -> 0
A26: 24 | B26: 1150511 | C26: 1150511 | D26: 8 | E26: =VLOOKUP($D26,客戶編輯設定自動代出!$A:$C,3,0) -> 路人 | F26: =VLOOKUP($D26,客戶編輯設定自動代出!$A:$C,2,0) -> 0 | G26: ZY23047018 | H26: 輪胎定位 | I26: 1 | J26: 2000 | K26: =I26*J26 -> 2000 | L26: 2100 | M26: =L26/1.05 -> 2000 | N26: 100 | O26: =IF($K26=$L26,"Y","N") -> N | P26: 刷卡 | Q26: 5242557139031682 | R26: 林祐竹 | V26: 24 | Z26: =VLOOKUP($Y26,客戶編輯設定自動代出!$A:$C,3,0) -> #N/A | AA26: =VLOOKUP($Y26,客戶編輯設定自動代出!$A:$C,2,0) -> #N/A | AB26: ZY23047272 | AF26: =AD26*AE26 -> 0 | AH26: =AG26/1.05 -> 0 | AI26: =AH26*0.05 -> 0 | AJ26: =IF($AF26=$AG26,"Y","N") -> Y | AQ26: 24 | AU26: =VLOOKUP($AT26,客戶編輯設定自動代出!$A:$C,3,0) -> #N/A | AV26: =VLOOKUP($AT26,客戶編輯設定自動代出!$A:$C,2,0) -> #N/A | AW26: ZX57093923 | BA26: =AY26*AZ26 -> 0 | BC26: =BB26/1.05 -> 0 | BD26: =BC26*0.05 -> 0 | BE26: =IF($BB26=$BA26,"Y","N") -> Y | BJ26: 24 | BM26: =VLOOKUP(BL26,[1]客戶編輯設定自動代出!L:N,3,0) -> #N/A | BN26: =VLOOKUP(BL26,[1]客戶編輯設定自動代出!L:N,2,0) -> #N/A | BO26: ZZ39642573 | BQ26: =BP26/1.05 -> 0 | BR26: =BQ26*0.05 -> 0
A27: 25 | B27: 1150511 | C27: 1150511 | D27: 481 | E27: =VLOOKUP($D27,客戶編輯設定自動代出!$A:$C,3,0) -> 後龍鎮公所 | F27: =VLOOKUP($D27,客戶編輯設定自動代出!$A:$C,2,0) -> 50402704 | G27: ZY23047019 | H27: 輪胎 | I27: 8 | J27: 6750 | K27: =I27*J27 -> 54000 | L27: 54000 | M27: =L27/1.05 -> 51428.571 | N27: 2571 | O27: =IF($K27=$L27,"Y","N") -> Y | P27: 匯款 | R27: 林祐竹 | V27: 25 | Z27: =VLOOKUP($Y27,客戶編輯設定自動代出!$A:$C,3,0) -> #N/A | AA27: =VLOOKUP($Y27,客戶編輯設定自動代出!$A:$C,2,0) -> #N/A | AB27: ZY23047273 | AF27: =AD27*AE27 -> 0 | AH27: =AG27/1.05 -> 0 | AI27: =AH27*0.05 -> 0 | AJ27: =IF($AF27=$AG27,"Y","N") -> Y | AQ27: 25 | AU27: =VLOOKUP($AT27,客戶編輯設定自動代出!$A:$C,3,0) -> #N/A | AV27: =VLOOKUP($AT27,客戶編輯設定自動代出!$A:$C,2,0) -> #N/A | AW27: ZX57093924 | BA27: =AY27*AZ27 -> 0 | BC27: =BB27/1.05 -> 0 | BD27: =BC27*0.05 -> 0 | BE27: =IF($BB27=$BA27,"Y","N") -> Y | BJ27: 25 | BM27: =VLOOKUP(BL27,[1]客戶編輯設定自動代出!L:N,3,0) -> #N/A | BN27: =VLOOKUP(BL27,[1]客戶編輯設定自動代出!L:N,2,0) -> #N/A | BO27: ZZ39642574 | BQ27: =BP27/1.05 -> 0 | BR27: =BQ27*0.05 -> 0
A28: 26 | B28: 1150513 | C28: 1150513 | D28: 784 | E28: =VLOOKUP($D28,客戶編輯設定自動代出!$A:$C,3,0) -> 台北合眾汽車有限公司 | F28: =VLOOKUP($D28,客戶編輯設定自動代出!$A:$C,2,0) -> 53352812 | G28: ZY23047020 | H28: 輪胎定位 | I28: 1 | J28: 2500 | K28: =I28*J28 -> 2500 | L28: 2500 | M28: =L28/1.05 -> 2380.9524 | N28: 119 | O28: =IF($K28=$L28,"Y","N") -> Y | P28: 匯款 | R28: 林祐竹 | V28: 26 | Z28: =VLOOKUP($Y28,客戶編輯設定自動代出!$A:$C,3,0) -> #N/A | AA28: =VLOOKUP($Y28,客戶編輯設定自動代出!$A:$C,2,0) -> #N/A | AB28: ZY23047274 | AF28: =AD28*AE28 -> 0 | AH28: =AG28/1.05 -> 0 | AI28: =AH28*0.05 -> 0 | AJ28: =IF($AF28=$AG28,"Y","N") -> Y | AQ28: 26 | AU28: =VLOOKUP($AT28,客戶編輯設定自動代出!$A:$C,3,0) -> #N/A | AV28: =VLOOKUP($AT28,客戶編輯設定自動代出!$A:$C,2,0) -> #N/A | AW28: ZX57093925 | BA28: =AY28*AZ28 -> 0 | BC28: =BB28/1.05 -> 0 | BD28: =BC28*0.05 -> 0 | BE28: =IF($BB28=$BA28,"Y","N") -> Y | BJ28: 26 | BM28: =VLOOKUP(BL28,[1]客戶編輯設定自動代出!L:N,3,0) -> #N/A | BN28: =VLOOKUP(BL28,[1]客戶編輯設定自動代出!L:N,2,0) -> #N/A | BO28: ZZ39642575 | BQ28: =BP28/1.05 -> 0 | BR28: =BQ28*0.05 -> 0
A29: 27 | B29: 1150514 | C29: 1150514 | D29: 8 | E29: =VLOOKUP($D29,客戶編輯設定自動代出!$A:$C,3,0) -> 路人 | F29: 80773631 | G29: ZY23047021 | H29: 輪胎 | I29: 3 | J29: 3800 | K29: =I29*J29 -> 11400 | L29: 11970 | M29: =L29/1.05 -> 11400 | N29: 570 | O29: =IF($K29=$L29,"Y","N") -> N | P29: 刷卡 | Q29: 5521973104911356 | R29: 黃珮綺 | V29: 27 | Z29: =VLOOKUP($Y29,客戶編輯設定自動代出!$A:$C,3,0) -> #N/A | AA29: =VLOOKUP($Y29,客戶編輯設定自動代出!$A:$C,2,0) -> #N/A | AB29: ZY23047275 | AF29: =AD29*AE29 -> 0 | AH29: =AG29/1.05 -> 0 | AI29: =AH29*0.05 -> 0 | AJ29: =IF($AF29=$AG29,"Y","N") -> Y | AQ29: 27 | AU29: =VLOOKUP($AT29,客戶編輯設定自動代出!$A:$C,3,0) -> #N/A | AV29: =VLOOKUP($AT29,客戶編輯設定自動代出!$A:$C,2,0) -> #N/A | AW29: ZX57093926 | BA29: =AY29*AZ29 -> 0 | BC29: =BB29/1.05 -> 0 | BD29: =BC29*0.05 -> 0 | BE29: =IF($BB29=$BA29,"Y","N") -> Y | BJ29: 27 | BM29: =VLOOKUP(BL29,[1]客戶編輯設定自動代出!L:N,3,0) -> #N/A | BN29: =VLOOKUP(BL29,[1]客戶編輯設定自動代出!L:N,2,0) -> #N/A | BO29: ZZ39642576 | BQ29: =BP29/1.05 -> 0 | BR29: =BQ29*0.05 -> 0
A30: 28 | B30: 1150515 | C30: 1150515 | D30: 8 | E30: =VLOOKUP($D30,客戶編輯設定自動代出!$A:$C,3,0) -> 路人 | F30: =VLOOKUP($D30,客戶編輯設定自動代出!$A:$C,2,0) -> 0 | G30: ZY23047022 | H30: 輪胎 | I30: 1 | J30: 2500 | K30: =I30*J30 -> 2500 | L30: 2625 | M30: =L30/1.05 -> 2500 | N30: 125 | O30: =IF($K30=$L30,"Y","N") -> N | P30: 刷卡 | Q30: 5521973701527951 | R30: 黃珮綺 | V30: 28 | Z30: =VLOOKUP($Y30,客戶編輯設定自動代出!$A:$C,3,0) -> #N/A | AA30: =VLOOKUP($Y30,客戶編輯設定自動代出!$A:$C,2,0) -> #N/A | AB30: ZY23047276 | AF30: =AD30*AE30 -> 0 | AH30: =AG30/1.05 -> 0 | AI30: =AH30*0.05 -> 0 | AJ30: =IF($AF30=$AG30,"Y","N") -> Y | AQ30: 28 | AU30: =VLOOKUP($AT30,客戶編輯設定自動代出!$A:$C,3,0) -> #N/A | AV30: =VLOOKUP($AT30,客戶編輯設定自動代出!$A:$C,2,0) -> #N/A | AW30: ZX57093927 | BA30: =AY30*AZ30 -> 0 | BC30: =BB30/1.05 -> 0 | BD30: =BC30*0.05 -> 0 | BE30: =IF($BB30=$BA30,"Y","N") -> Y | BJ30: 28 | BM30: =VLOOKUP(BL30,[1]客戶編輯設定自動代出!L:N,3,0) -> #N/A | BN30: =VLOOKUP(BL30,[1]客戶編輯設定自動代出!L:N,2,0) -> #N/A | BO30: ZZ39642577 | BQ30: =BP30/1.05 -> 0 | BR30: =BQ30*0.05 -> 0
A31: 29 | B31: 1150518 | C31: 1150518 | D31: 8 | E31: =VLOOKUP($D31,客戶編輯設定自動代出!$A:$C,3,0) -> 路人 | F31: 27863346 | G31: ZY23047023 | H31: 輪胎 | I31: 2 | J31: 15800 | K31: =I31*J31 -> 31600 | L31: 33180 | M31: =L31/1.05 -> 31600 | N31: 1580 | O31: =IF($K31=$L31,"Y","N") -> N | P31: 刷卡 | Q31: 4705720202203603 | R31: 林祐竹 | V31: 29 | Z31: =VLOOKUP($Y31,客戶編輯設定自動代出!$A:$C,3,0) -> #N/A | AA31: =VLOOKUP($Y31,客戶編輯設定自動代出!$A:$C,2,0) -> #N/A | AB31: ZY23047277 | AF31: =AD31*AE31 -> 0 | AH31: =AG31/1.05 -> 0 | AI31: =AH31*0.05 -> 0 | AJ31: =IF($AF31=$AG31,"Y","N") -> Y | AQ31: 29 | AU31: =VLOOKUP($AT31,客戶編輯設定自動代出!$A:$C,3,0) -> #N/A | AV31: =VLOOKUP($AT31,客戶編輯設定自動代出!$A:$C,2,0) -> #N/A | AW31: ZX57093928 | BA31: =AY31*AZ31 -> 0 | BC31: =BB31/1.05 -> 0 | BD31: =BC31*0.05 -> 0 | BE31: =IF($BB31=$BA31,"Y","N") -> Y | BJ31: 29 | BM31: =VLOOKUP(BL31,[1]客戶編輯設定自動代出!L:N,3,0) -> #N/A | BN31: =VLOOKUP(BL31,[1]客戶編輯設定自動代出!L:N,2,0) -> #N/A | BO31: ZZ39642578 | BQ31: =BP31/1.05 -> 0 | BR31: =BQ31*0.05 -> 0
A32: 30 | B32: 1150519 | C32: 1150519 | D32: 775 | E32: =VLOOKUP($D32,客戶編輯設定自動代出!$A:$C,3,0) -> 普利司通 | F32: =VLOOKUP($D32,客戶編輯設定自動代出!$A:$C,2,0) -> 12749608 | G32: ZY23047024 | H32: 工資 | I32: 1 | J32: 1300 | K32: =I32*J32 -> 1300 | L32: 1365 | M32: =L32/1.05 -> 1300 | N32: 65 | O32: =IF($K32=$L32,"Y","N") -> N | P32: 匯款 | R32: 林祐竹 | V32: 30 | Z32: =VLOOKUP($Y32,客戶編輯設定自動代出!$A:$C,3,0) -> #N/A | AA32: =VLOOKUP($Y32,客戶編輯設定自動代出!$A:$C,2,0) -> #N/A | AB32: ZY23047278 | AF32: =AD32*AE32 -> 0 | AH32: =AG32/1.05 -> 0 | AI32: =AH32*0.05 -> 0 | AJ32: =IF($AF32=$AG32,"Y","N") -> Y | AQ32: 30 | AU32: =VLOOKUP($AT32,客戶編輯設定自動代出!$A:$C,3,0) -> #N/A | AV32: =VLOOKUP($AT32,客戶編輯設定自動代出!$A:$C,2,0) -> #N/A | AW32: ZX57093929 | BA32: =AY32*AZ32 -> 0 | BC32: =BB32/1.05 -> 0 | BD32: =BC32*0.05 -> 0 | BE32: =IF($BB32=$BA32,"Y","N") -> Y | BJ32: 30 | BM32: =VLOOKUP(BL32,[1]客戶編輯設定自動代出!L:N,3,0) -> #N/A | BN32: =VLOOKUP(BL32,[1]客戶編輯設定自動代出!L:N,2,0) -> #N/A | BO32: ZZ39642579 | BQ32: =BP32/1.05 -> 0 | BR32: =BQ32*0.05 -> 0
A33: 31 | B33: 1150520 | C33: 1150520 | D33: 8 | E33: =VLOOKUP($D33,客戶編輯設定自動代出!$A:$C,3,0) -> 路人 | F33: 70626941 | G33: ZY23047025 | H33: 輪胎 | I33: 1 | J33: 5800 | K33: =I33*J33 -> 5800 | L33: 6090 | M33: =L33/1.05 -> 5800 | N33: 290 | O33: =IF($K33=$L33,"Y","N") -> N | P33: 刷卡 | Q33: 4688288020692606 | R33: 林祐竹 | V33: 31 | Z33: =VLOOKUP($Y33,客戶編輯設定自動代出!$A:$C,3,0) -> #N/A | AA33: =VLOOKUP($Y33,客戶編輯設定自動代出!$A:$C,2,0) -> #N/A | AB33: ZY23047279 | AF33: =AD33*AE33 -> 0 | AH33: =AG33/1.05 -> 0 | AI33: =AH33*0.05 -> 0 | AJ33: =IF($AF33=$AG33,"Y","N") -> Y | AQ33: 31 | AU33: =VLOOKUP($AT33,客戶編輯設定自動代出!$A:$C,3,0) -> #N/A | AV33: =VLOOKUP($AT33,客戶編輯設定自動代出!$A:$C,2,0) -> #N/A | AW33: ZX57093930 | BA33: =AY33*AZ33 -> 0 | BC33: =BB33/1.05 -> 0 | BD33: =BC33*0.05 -> 0 | BE33: =IF($BB33=$BA33,"Y","N") -> Y | BJ33: 31 | BM33: =VLOOKUP(BL33,[1]客戶編輯設定自動代出!L:N,3,0) -> #N/A | BN33: =VLOOKUP(BL33,[1]客戶編輯設定自動代出!L:N,2,0) -> #N/A | BO33: ZZ39642580 | BQ33: =BP33/1.05 -> 0 | BR33: =BQ33*0.05 -> 0
A34: 32 | B34: 1150520 | C34: 1150520 | D34: 8 | E34: =VLOOKUP($D34,客戶編輯設定自動代出!$A:$C,3,0) -> 路人 | F34: 90106047 | G34: ZY23047026 | H34: 輪胎 | I34: 4 | J34: 5800 | K34: =I34*J34 -> 23200 | L34: 24360 | M34: =L34/1.05 -> 23200 | N34: 1160 | O34: =IF($K34=$L34,"Y","N") -> N | P34: 刷卡 | Q34: 4182303502472962 | R34: 林祐竹 | V34: 32 | Z34: =VLOOKUP($Y34,客戶編輯設定自動代出!$A:$C,3,0) -> #N/A | AA34: =VLOOKUP($Y34,客戶編輯設定自動代出!$A:$C,2,0) -> #N/A | AB34: ZY23047279 | AF34: =AD34*AE34 -> 0 | AH34: =AG34/1.05 -> 0 | AI34: =AH34*0.05 -> 0 | AJ34: =IF($AF34=$AG34,"Y","N") -> Y | AQ34: 32 | AU34: =VLOOKUP($AT34,客戶編輯設定自動代出!$A:$C,3,0) -> #N/A | AV34: =VLOOKUP($AT34,客戶編輯設定自動代出!$A:$C,2,0) -> #N/A | AW34: ZX57093931 | BA34: =AY34*AZ34 -> 0 | BC34: =BB34/1.05 -> 0 | BD34: =BC34*0.05 -> 0 | BE34: =IF($BB34=$BA34,"Y","N") -> Y | BJ34: 32 | BM34: =VLOOKUP(BL34,[1]客戶編輯設定自動代出!L:N,3,0) -> #N/A | BN34: =VLOOKUP(BL34,[1]客戶編輯設定自動代出!L:N,2,0) -> #N/A | BO34: ZZ39642581 | BQ34: =BP34/1.05 -> 0 | BR34: =BQ34*0.05 -> 0
A35: 33 | B35: 1150520 | C35: 1150520 | D35: 8 | E35: =VLOOKUP($D35,客戶編輯設定自動代出!$A:$C,3,0) -> 路人 | F35: 83092080 | G35: ZY23047027 | H35: 中古機器 | I35: 1 | J35: 250000 | K35: =I35*J35 -> 250000 | L35: 262500 | M35: =L35/1.05 -> 250000 | N35: 12500 | O35: =IF($K35=$L35,"Y","N") -> N | P35: 匯款 | R35: 林祐竹 | V35: 33 | Z35: =VLOOKUP($Y35,客戶編輯設定自動代出!$A:$C,3,0) -> #N/A | AA35: =VLOOKUP($Y35,客戶編輯設定自動代出!$A:$C,2,0) -> #N/A | AB35: ZY23047280 | AF35: =AD35*AE35 -> 0 | AH35: =AG35/1.05 -> 0 | AI35: =AH35*0.05 -> 0 | AJ35: =IF($AF35=$AG35,"Y","N") -> Y | AQ35: 33 | AU35: =VLOOKUP($AT35,客戶編輯設定自動代出!$A:$C,3,0) -> #N/A | AV35: =VLOOKUP($AT35,客戶編輯設定自動代出!$A:$C,2,0) -> #N/A | AW35: ZX57093932 | BA35: =AY35*AZ35 -> 0 | BC35: =BB35/1.05 -> 0 | BD35: =BC35*0.05 -> 0 | BE35: =IF($BB35=$BA35,"Y","N") -> Y | BJ35: 33 | BM35: =VLOOKUP(BL35,[1]客戶編輯設定自動代出!L:N,3,0) -> #N/A | BN35: =VLOOKUP(BL35,[1]客戶編輯設定自動代出!L:N,2,0) -> #N/A | BO35: ZZ39642582 | BQ35: =BP35/1.05 -> 0 | BR35: =BQ35*0.05 -> 0
A36: 34 | B36: 1150520 | C36: 1150520 | D36: 83 | E36: =VLOOKUP($D36,客戶編輯設定自動代出!$A:$C,3,0) -> 觀鼎 | F36: 97419282 | G36: ZY23047028 | H36: 輪胎 | I36: 10 | J36: 5807 | K36: =I36*J36 -> 58070 | L36: 58070 | M36: =L36/1.05 -> 55304.762 | N36: 2765 | O36: =IF($K36=$L36,"Y","N") -> Y | P36: 匯款 | R36: 林祐竹 | V36: 34 | Z36: =VLOOKUP($Y36,客戶編輯設定自動代出!$A:$C,3,0) -> #N/A | AA36: =VLOOKUP($Y36,客戶編輯設定自動代出!$A:$C,2,0) -> #N/A | AB36: ZY23047281 | AF36: =AD36*AE36 -> 0 | AH36: =AG36/1.05 -> 0 | AI36: =AH36*0.05 -> 0 | AJ36: =IF($AF36=$AG36,"Y","N") -> Y | AQ36: 34 | AU36: =VLOOKUP($AT36,客戶編輯設定自動代出!$A:$C,3,0) -> #N/A | AV36: =VLOOKUP($AT36,客戶編輯設定自動代出!$A:$C,2,0) -> #N/A | AW36: ZX57093933 | BA36: =AY36*AZ36 -> 0 | BC36: =BB36/1.05 -> 0 | BD36: =BC36*0.05 -> 0 | BE36: =IF($BB36=$BA36,"Y","N") -> Y | BJ36: 34 | BM36: =VLOOKUP(BL36,[1]客戶編輯設定自動代出!L:N,3,0) -> #N/A | BN36: =VLOOKUP(BL36,[1]客戶編輯設定自動代出!L:N,2,0) -> #N/A | BO36: ZZ39642583 | BQ36: =BP36/1.05 -> 0 | BR36: =BQ36*0.05 -> 0
A37: 35 | B37: 1150520 | C37: 1150520 | D37: 83 | E37: =VLOOKUP($D37,客戶編輯設定自動代出!$A:$C,3,0) -> 觀鼎 | F37: =VLOOKUP($D37,客戶編輯設定自動代出!$A:$C,2,0) -> 47289215 | G37: ZY23047029 | H37: 輪胎 | I37: 4 | J37: 11000 | K37: =I37*J37 -> 44000 | L37: 44000 | M37: =L37/1.05 -> 41904.762 | N37: 2095 | O37: =IF($K37=$L37,"Y","N") -> Y | P37: 匯款 | R37: 林祐竹 | V37: 35 | Z37: =VLOOKUP($Y37,客戶編輯設定自動代出!$A:$C,3,0) -> #N/A | AA37: =VLOOKUP($Y37,客戶編輯設定自動代出!$A:$C,2,0) -> #N/A | AB37: ZY23047282 | AF37: =AD37*AE37 -> 0 | AH37: =AG37/1.05 -> 0 | AI37: =AH37*0.05 -> 0 | AJ37: =IF($AF37=$AG37,"Y","N") -> Y | AQ37: 35 | AU37: =VLOOKUP($AT37,客戶編輯設定自動代出!$A:$C,3,0) -> #N/A | AV37: =VLOOKUP($AT37,客戶編輯設定自動代出!$A:$C,2,0) -> #N/A | AW37: ZX57093934 | BA37: =AY37*AZ37 -> 0 | BC37: =BB37/1.05 -> 0 | BD37: =BC37*0.05 -> 0 | BE37: =IF($BB37=$BA37,"Y","N") -> Y | BJ37: 35 | BM37: =VLOOKUP(BL37,[1]客戶編輯設定自動代出!L:N,3,0) -> #N/A | BN37: =VLOOKUP(BL37,[1]客戶編輯設定自動代出!L:N,2,0) -> #N/A | BO37: ZZ39642584 | BQ37: =BP37/1.05 -> 0 | BR37: =BQ37*0.05 -> 0
A38: 36 | B38: 1150520 | C38: 1150520 | D38: 531 | E38: =VLOOKUP($D38,客戶編輯設定自動代出!$A:$C,3,0) -> 鋒魁 | F38: 28772230 | G38: ZY23047030 | K38: =I38*J38 -> 0 | M38: =L38/1.05 -> 0 | O38: 作廢 | R38: 林祐竹 | V38: 36 | Z38: =VLOOKUP($Y38,客戶編輯設定自動代出!$A:$C,3,0) -> #N/A | AA38: =VLOOKUP($Y38,客戶編輯設定自動代出!$A:$C,2,0) -> #N/A | AB38: ZY23047283 | AF38: =AD38*AE38 -> 0 | AH38: =AG38/1.05 -> 0 | AI38: =AH38*0.05 -> 0 | AJ38: =IF($AF38=$AG38,"Y","N") -> Y | AQ38: 36 | AU38: =VLOOKUP($AT38,客戶編輯設定自動代出!$A:$C,3,0) -> #N/A | AV38: =VLOOKUP($AT38,客戶編輯設定自動代出!$A:$C,2,0) -> #N/A | AW38: ZX57093935 | BA38: =AY38*AZ38 -> 0 | BC38: =BB38/1.05 -> 0 | BD38: =BC38*0.05 -> 0 | BE38: =IF($BB38=$BA38,"Y","N") -> Y | BJ38: 36 | BM38: =VLOOKUP(BL38,[1]客戶編輯設定自動代出!L:N,3,0) -> #N/A | BN38: =VLOOKUP(BL38,[1]客戶編輯設定自動代出!L:N,2,0) -> #N/A | BO38: ZZ39642585 | BQ38: =BP38/1.05 -> 0 | BR38: =BQ38*0.05 -> 0
A39: 37 | B39: 1150520 | C39: 1150520 | D39: 531 | E39: =VLOOKUP($D39,客戶編輯設定自動代出!$A:$C,3,0) -> 鋒魁 | F39: =VLOOKUP($D39,客戶編輯設定自動代出!$A:$C,2,0) -> 28772230 | G39: ZY23047031 | H39: 補胎 | I39: 1 | J39: 900 | K39: =I39*J39 -> 900 | L39: 945 | M39: =L39/1.05 -> 900 | N39: 45 | O39: =IF($K39=$L39,"Y","N") -> N | P39: 匯款 | R39: 林祐竹 | V39: 37 | Z39: =VLOOKUP($Y39,客戶編輯設定自動代出!$A:$C,3,0) -> #N/A | AA39: =VLOOKUP($Y39,客戶編輯設定自動代出!$A:$C,2,0) -> #N/A | AB39: ZY23047284 | AF39: =AD39*AE39 -> 0 | AH39: =AG39/1.05 -> 0 | AI39: =AH39*0.05 -> 0 | AJ39: =IF($AF39=$AG39,"Y","N") -> Y | AQ39: 37 | AU39: =VLOOKUP($AT39,客戶編輯設定自動代出!$A:$C,3,0) -> #N/A | AV39: =VLOOKUP($AT39,客戶編輯設定自動代出!$A:$C,2,0) -> #N/A | AW39: ZX57093936 | BA39: =AY39*AZ39 -> 0 | BC39: =BB39/1.05 -> 0 | BD39: =BC39*0.05 -> 0 | BE39: =IF($BB39=$BA39,"Y","N") -> Y | BJ39: 37 | BM39: =VLOOKUP(BL39,[1]客戶編輯設定自動代出!L:N,3,0) -> #N/A | BN39: =VLOOKUP(BL39,[1]客戶編輯設定自動代出!L:N,2,0) -> #N/A | BO39: ZZ39642586 | BQ39: =BP39/1.05 -> 0 | BR39: =BQ39*0.05 -> 0
A40: 38 | B40: 1150520 | C40: 1150520 | D40: 8 | E40: =VLOOKUP($D40,客戶編輯設定自動代出!$A:$C,3,0) -> 路人 | F40: 42963288 | G40: ZY23047032 | H40: 輪胎 | I40: 2 | J40: 5800 | K40: =I40*J40 -> 11600 | L40: 12180 | M40: =L40/1.05 -> 11600 | N40: 580 | O40: =IF($K40=$L40,"Y","N") -> N | P40: 刷卡 | Q40: 4162050102172609 | R40: 林祐竹 | V40: 38 | Z40: =VLOOKUP($Y40,客戶編輯設定自動代出!$A:$C,3,0) -> #N/A | AA40: =VLOOKUP($Y40,客戶編輯設定自動代出!$A:$C,2,0) -> #N/A | AB40: ZY23047285 | AF40: =AD40*AE40 -> 0 | AH40: =AG40/1.05 -> 0 | AI40: =AH40*0.05 -> 0 | AJ40: =IF($AF40=$AG40,"Y","N") -> Y | AQ40: 38 | AU40: =VLOOKUP($AT40,客戶編輯設定自動代出!$A:$C,3,0) -> #N/A | AV40: =VLOOKUP($AT40,客戶編輯設定自動代出!$A:$C,2,0) -> #N/A | AW40: ZX57093937 | BA40: =AY40*AZ40 -> 0 | BC40: =BB40/1.05 -> 0 | BD40: =BC40*0.05 -> 0 | BE40: =IF($BB40=$BA40,"Y","N") -> Y | BJ40: 38 | BM40: =VLOOKUP(BL40,[1]客戶編輯設定自動代出!L:N,3,0) -> #N/A | BN40: =VLOOKUP(BL40,[1]客戶編輯設定自動代出!L:N,2,0) -> #N/A | BO40: ZZ39642587 | BQ40: =BP40/1.05 -> 0 | BR40: =BQ40*0.05 -> 0
...

Sheet 中華全佑27911467-營業稅扣抵
A1: 中華全佑 | E1: 115-05~06 | F1: 進項-營業稅申報 | M1: =SUM(M3:M209) -> 495919 | N1: =SUM(N3:N209) -> 472304.71 | O1: =SUM(O3:O209) -> 23615.333
A2: 序號 | B2: 登入日期 | C2: 年月日 | D2: 廠編 | E2: 廠商簡稱 | F2: 統一編號 | G2: 發票號碼 | H2: 發票型式 | I2: 品項 | J2: 數量 | K2: 單價 | L2: 小計 | M2: 發票總額 | N2: 未稅金額 | O2: 稅額 | P2: 備註 | Q2: 工作人員 | R2: 核對人1 | S2: 核對人2 | T2: 核對人3 | U2: 已申報
A3: 1 | B3: 1150505 | C3: 1150504 | E3: 車亭竹南站 | F3: 38903921 | G3: BC27744362 | H3: 電子發票-(電子發票證明聯) | I3: 柴油 | J3: 45.16 | K3: 31 | L3: =J3*K3 -> 1399.96 | M3: 1400 | N3: =M3/1.05 -> 1333.3333 | O3: 67 | Q3: 林祐竹
A4: 2 | B4: 1150505 | C4: 1150504 | E4: 車亭竹南站 | F4: 38903921 | G4: BC27744366 | H4: 電子發票-(電子發票證明聯) | I4: 柴油 | J4: 32.25 | K4: 31 | L4: =J4*K4 -> 999.75 | M4: 1000 | N4: =M4/1.05 -> 952.38095 | O4: 48 | Q4: 林祐竹
A5: 3 | B5: 1150505 | C5: 1150501 | E5: 車亭竹南站 | F5: 38903921 | G5: BC27735518 | H5: 電子發票-(電子發票證明聯) | I5: 柴油 | J5: 74.21 | K5: 31 | L5: =J5*K5 -> 2300.51 | M5: 2301 | N5: =M5/1.05 -> 2191.4286 | O5: 110 | Q5: 林祐竹
A6: 4 | B6: 1150505 | C6: 1150501 | E6: 車亭竹南二站 | F6: 38960823 | G6: BF99190077 | H6: 電子發票-(電子發票證明聯) | I6: 柴油 | J6: 64.51 | K6: 31 | L6: =J6*K6 -> 1999.81 | M6: 2000 | N6: =M6/1.05 -> 1904.7619 | O6: 95 | Q6: 林祐竹
A7: 5 | B7: 1150506 | C7: 1150505 | E7: 車亭竹南二站 | F7: 38960823 | G7: BF99205740 | H7: 電子發票-(電子發票證明聯) | I7: 柴油 | J7: 32.25 | K7: 31 | L7: =J7*K7 -> 999.75 | M7: 1000 | N7: =M7/1.05 -> 952.38095 | O7: 48 | Q7: 林祐竹
A8: 6 | B8: 1150506 | C8: 1150504 | E8: 車亭竹南二站 | F8: 38960823 | G8: BF99205666 | H8: 電子發票-(電子發票證明聯) | I8: 柴油 | J8: 64.51 | K8: 31 | L8: =J8*K8 -> 1999.81 | M8: 1000 | N8: =M8/1.05 -> 952.38095 | O8: 48 | Q8: 林祐竹
A9: 7 | B9: 1150508 | C9: 1150503 | E9: 台灣中油 | F9: 88605975 | G9: AR20070200 | H9: 電子發票-(電子發票證明聯) | I9: 95無鉛 | J9: 59.168 | K9: 33.9 | L9: =J9*K9 -> 2005.7952 | M9: 2006 | N9: =M9/1.05 -> 1910.4762 | O9: 96 | Q9: 黃珮綺
A10: 8 | B10: 1150509 | C10: 1150508 | E10: 車亭竹南二站 | F10: 38960823 | G10: BF99206289 | H10: 電子發票-(電子發票證明聯) | I10: 柴油 | J10: 64.5 | K10: 31 | L10: =J10*K10 -> 1999.5 | M10: 2000 | N10: =M10/1.05 -> 1904.7619 | O10: 95 | Q10: 林祐竹
A11: 9 | B11: 1150512 | C11: 1150511 | E11: 車亭竹南站 | F11: 38903921 | G11: BC27744767 | H11: 電子發票-(電子發票證明聯) | I11: 柴油 | J11: 48.38 | K11: 31 | L11: =J11*K11 -> 1499.78 | M11: 1500 | N11: =M11/1.05 -> 1428.5714 | O11: 71 | Q11: 黃珮綺
A12: 10 | B12: 1150507 | C12: 1150502 | D12: 5 | E12: 米其林(公司)-大胎 | F12: 70357185 | G12: ZA65691630 | H12: 退折證明單-(折讓) | I12: 輪胎 | J12: 1 | K12: -633 | L12: -633 | M12: -665 | N12: -633.33333 | O12: =N12*0.05 -> -31.666667 | Q12: 林祐竹
A13: 11 | B13: 1150513 | C13: 1150512 | E13: 建興加油站 | F13: 70714536 | G13: BD72999099 | H13: 電子發票-(電子發票證明聯) | I13: 柴油 | J13: 77.45 | K13: 31 | L13: =J13*K13 -> 2400.95 | M13: 2401 | N13: =M13/1.05 -> 2286.6667 | O13: 114 | Q13: 林祐竹
A14: 12 | B14: 1150514 | C14: 1150513 | E14: 順豐速運 | F14: 28483484 | G14: BA87571186 | H14: 電子發票-(電子發票證明聯) | I14: 代墊稅金服務費 | J14: 1 | K14: 30 | L14: =J14*K14 -> 30 | M14: 30 | N14: =M14/1.05 -> 28.571429 | O14: 1 | Q14: 林祐竹
A15: 13 | B15: 1150514 | C15: 1150513 | E15: 車亭竹南站 | F15: 38903921 | G15: BC27744921 | H15: 電子發票-(電子發票證明聯) | I15: 柴油 | J15: 64.5 | K15: 31 | L15: =J15*K15 -> 1999.5 | M15: 2000 | N15: =M15/1.05 -> 1904.7619 | O15: 95 | Q15: 林祐竹
A16: 14 | B16: 1150514 | C16: 1150513 | E16: 車亭竹南二站 | F16: 38960823 | G16: BF99191709 | H16: 電子發票-(電子發票證明聯) | I16: 柴油 | J16: 119.36 | K16: 31 | L16: =J16*K16 -> 3700.16 | M16: 3700 | N16: =M16/1.05 -> 3523.8095 | O16: 176 | Q16: 林祐竹
A17: 15 | B17: 1150515 | C17: 1150512 | D17: 175 | E17: =VLOOKUP($D17,廠商編輯設定自動代出!$A:$C,2,0) -> 南冠輪胎 | F17: =VLOOKUP($D17,廠商編輯設定自動代出!$A:$C,3,0) -> 98746762 | G17: BK90301471 | H17: 電子發票-(電子發票證明聯) | I17: 輪胎 | J17: 20 | K17: 1952.38 | L17: =J17*K17 -> 39047.6 | M17: 41000 | N17: =M17/1.05 -> 39047.619 | O17: 1952 | Q17: 黃珮綺
A18: 16 | B18: 1150516 | C18: 1150514 | E18: 福樂加油站 | F18: 16212867 | G18: AZ20325768 | H18: 電子發票-(電子發票證明聯) | I18: 柴油 | J18: 64.51 | K18: 31 | L18: =J18*K18 -> 1999.81 | M18: 2000 | N18: =M18/1.05 -> 1904.7619 | O18: 95 | Q18: 黃珮綺
A19: 17 | B19: 1150518 | C19: 1150516 | E19: 國利加油站 | F19: 47412427 | G19: BC71436362 | H19: 電子發票-(電子發票證明聯) | I19: 95無鉛 | J19: 14.749 | K19: 33.9 | L19: =J19*K19 -> 499.9911 | M19: 500 | N19: =M19/1.05 -> 476.19048 | O19: 24 | Q19: 黃珮綺
A20: 18 | B20: 1150518 | C20: 1150517 | E20: 振宇五金 | F20: 42870872 | G20: AN03273537 | H20: 電子發票-(電子發票證明聯) | I20: 店用耗材 | J20: 1 | K20: 947 | L20: =J20*K20 -> 947 | M20: 997 | N20: =M20/1.05 -> 949.52381 | O20: 47 | Q20: 黃珮綺
A21: 19 | B21: 1150520 | C21: 1150516 | E21: 金典書局 | F21: 76927228 | G21: AA75135901 | H21: 電子發票-(電子發票證明聯) | I21: 文具 | J21: 1 | K21: 130 | L21: =J21*K21 -> 130 | M21: 130 | N21: =M21/1.05 -> 123.80952 | O21: 6 | Q21: 林祐竹
A22: 20 | B22: 1150520 | C22: 1150518 | E22: 車亭竹南站 | F22: 38903921 | G22: BC27756606 | H22: 電子發票-(電子發票證明聯) | I22: 92無鉛 | J22: 13.12 | K22: 32.4 | L22: =J22*K22 -> 425.088 | M22: 425 | N22: =M22/1.05 -> 404.7619 | O22: 20 | Q22: 林祐竹
A23: 21 | B23: 1150520 | C23: 1150518 | E23: 車亭竹南站 | F23: 38903921 | G23: BC27745157 | H23: 電子發票-(電子發票證明聯) | I23: 柴油 | J23: 50.81 | K23: 31 | L23: =J23*K23 -> 1575.11 | M23: 1575 | N23: =M23/1.05 -> 1500 | O23: 75 | Q23: 林祐竹
A24: 22 | B24: 1150520 | C24: 1150518 | E24: 全國電子 | F24: 16319880 | G24: AZ49715415 | H24: 電子發票-(電子發票證明聯) | I24: 印表機 | J24: 1 | K24: 1990 | L24: =J24*K24 -> 1990 | M24: 1990 | N24: =M24/1.05 -> 1895.2381 | O24: 95 | Q24: 林祐竹
A25: 23 | B25: 1150520 | C25: 1150508 | G25: DAI31158123119 | H25: 稅費繳納證 | I25: 拆胎機 | J25: 1 | K25: 194851 | L25: 192799 | M25: 192799 | N25: 183619 | O25: 9180 | P25: 百世拓1 | Q25: 林祐竹
A26: 24 | B26: 1150520 | C26: 1150515 | D26: 414 | E26: 鴻洲 | F26: 96831762 | G26: BP97452407 | H26: 電子發票-(電子發票證明聯) | I26: 運費 | J26: 1 | K26: 15157 | L26: =J26*K26 -> 15157 | M26: 15157 | N26: =M26/1.05 -> 14435.238 | O26: 722 | P26: 百世拓1 | Q26: 林祐竹
A27: 25 | B27: 1150520 | C27: 1150520 | D27: 175 | E27: =VLOOKUP($D27,廠商編輯設定自動代出!$A:$C,2,0) -> 南冠輪胎 | F27: =VLOOKUP($D27,廠商編輯設定自動代出!$A:$C,3,0) -> 98746762 | G27: BK90302064 | H27: 電子發票-(電子發票證明聯) | I27: 輪胎 | J27: 2 | K27: 5047.62 | L27: =J27*K27 -> 10095.24 | M27: 10600 | N27: =M27/1.05 -> 10095.238 | O27: 505 | Q27: 林祐竹
A28: 26 | B28: 1150522 | C28: 1150520 | E28: 車亭竹南二站 | F28: 38960823 | G28: BF99192677 | H28: 電子發票-(電子發票證明聯) | I28: 柴油 | J28: 70.97 | K28: 31 | L28: =J28*K28 -> 2200.07 | M28: 2200 | N28: =M28/1.05 -> 2095.2381 | O28: 105 | Q28: 林祐竹
A29: 27 | B29: 1150523 | C29: 1150521 | E29: 車亭竹南二站 | F29: 38960823 | G29: BF99208555 | H29: 電子發票-(電子發票證明聯) | I29: 95無鉛 | J29: 2.95 | K29: 33.9 | L29: =J29*K29 -> 100.005 | M29: 100 | N29: =M29/1.05 -> 95.238095 | O29: 5 | Q29: 林祐竹
A30: 28 | B30: 1150523 | C30: 1150522 | D30: 175 | E30: =VLOOKUP($D30,廠商編輯設定自動代出!$A:$C,2,0) -> 南冠輪胎 | F30: =VLOOKUP($D30,廠商編輯設定自動代出!$A:$C,3,0) -> 98746762 | G30: BK90302243 | H30: 電子發票-(電子發票證明聯) | I30: 輪胎一批 | J30: 1 | K30: 107300 | L30: =J30*K30 -> 107300 | M30: 107300 | N30: =M30/1.05 -> 102190.48 | O30: 5110 | Q30: 林祐竹
A31: 29 | B31: 1150523 | C31: 1150522 | D31: 175 | E31: =VLOOKUP($D31,廠商編輯設定自動代出!$A:$C,2,0) -> 南冠輪胎 | F31: =VLOOKUP($D31,廠商編輯設定自動代出!$A:$C,3,0) -> 98746762 | G31: BK90302248 | H31: 電子發票-(電子發票證明聯) | I31: 輪胎 | J31: 10 | K31: 4761.9 | L31: =J31*K31 -> 47619 | M31: 50000 | N31: =M31/1.05 -> 47619.048 | O31: 2381 | Q31: 林祐竹
A32: 30 | B32: 1150525 | C32: 1150519 | E32: 台灣中油 | F32: 42073525 | G32: AR47143749 | H32: 電子發票-(電子發票證明聯) | I32: 95無鉛 | J32: 107.46 | K32: 33.9 | L32: =J32*K32 -> 3642.894 | M32: 3643 | N32: =M32/1.05 -> 3469.5238 | O32: 173 | Q32: 黃珮綺
A33: 31 | B33: 1150527 | C33: 1150523 | E33: 車亭竹南站 | F33: 38903921 | G33: BC27757559 | H33: 電子發票-(電子發票證明聯) | I33: 95無鉛 | J33: 23.59 | K33: 33.9 | L33: =J33*K33 -> 799.701 | M33: 800 | N33: =M33/1.05 -> 761.90476 | O33: 38 | Q33: 林祐竹
A34: 32 | B34: 1150527 | C34: 1150523 | E34: 車亭竹南站 | F34: 38903921 | G34: BC27745344 | H34: 電子發票-(電子發票證明聯) | I34: 柴油 | J34: 46.44 | K34: 31 | L34: =J34*K34 -> 1439.64 | M34: 1440 | N34: =M34/1.05 -> 1371.4286 | O34: 69 | Q34: 林祐竹
A35: 33 | B35: 1150527 | C35: 1150523 | E35: 車亭竹南站 | F35: 38903921 | G35: BC27737126 | H35: 電子發票-(電子發票證明聯) | I35: 柴油 | J35: 75.81 | K35: 31 | L35: =J35*K35 -> 2350.11 | M35: 2350 | N35: =M35/1.05 -> 2238.0952 | O35: 112 | Q35: 林祐竹
A36: 34 | B36: 1150529 | C36: 1150527 | E36: 南北通二站 | F36: 94450422 | G36: BN79847232 | H36: 電子發票-(電子發票證明聯) | I36: 柴油 | J36: 32.25 | K36: 31 | L36: =J36*K36 -> 999.75 | M36: 1000 | N36: =M36/1.05 -> 952.38095 | O36: 48 | Q36: 林祐竹
A37: 35 | B37: 1150529 | C37: 1150527 | E37: 樂安消防 | F37: 60697392 | G37: BQ75659829 | H37: 電子發票-(電子發票證明聯) | I37: 消防器材 | J37: 1 | K37: 30000 | L37: =J37*K37 -> 30000 | M37: 31500 | N37: =M37/1.05 -> 30000 | O37: 1500 | Q37: 林祐竹
A38: 36 | B38: 1150530 | C38: 1150529 | E38: 台灣中油 | F38: 02938995 | G38: AR20660130 | H38: 電子發票-(電子發票證明聯) | I38: 去漬油 | J38: 24 | K38: 60 | L38: =J38*K38 -> 1440 | M38: 1440 | N38: =M38/1.05 -> 1371.4286 | O38: 69 | Q38: 林祐竹
A39: 37 | B39: 1150530 | C39: 1150529 | E39: 車亭竹南站 | F39: 38903921 | G39: BC27737499 | H39: 電子發票-(電子發票證明聯) | I39: 柴油 | J39: 64.51 | K39: 31 | L39: =J39*K39 -> 1999.81 | M39: 2000 | N39: =M39/1.05 -> 1904.7619 | O39: 95 | Q39: 林祐竹
A40: 38 | B40: 1150530 | C40: 1150529 | E40: 車亭竹南二站 | F40: 38960823 | G40: BF99193933 | H40: 電子發票-(電子發票證明聯) | I40: 柴油 | J40: 58.06 | K40: 31 | L40: =J40*K40 -> 1799.86 | M40: 1800 | N40: =M40/1.05 -> 1714.2857 | O40: 86 | Q40: 林祐竹
...

Sheet 中華全佑-費用扣抵
A1: 中華全佑 | D1: 115-05~06 | E1: 進項-不能扣抵營業稅 當費用 | L1: =SUM(L3:L42) -> 26215 | M1: =SUM(M3:M42) -> 24966.667 | N1: =SUM(N3:N42) -> 1248 | V1: 中華全佑 | Z1: 115-05~06 | AA1: 收據
A2: 序號 | B2: 登入日期 | C2: 年月日 | D2: 廠商簡稱 | E2: 統一編號 | F2: 發票號碼 | G2: 發票型式 | H2: 品項 | I2: 數量 | J2: 單價 | K2: 小計 | L2: 發票總額 | M2: 未稅金額 | N2: 稅額 | O2: 備註 | P2: 工作人員 | Q2: 核對人1 | R2: 核對人2 | S2: 核對人3 | T2: 已申報 | V2: 序號 | W2: 登入日期 | X2: 年月日 | Y2: 品名 | Z2: 金額 | AA2: 工作人員 | AB2: 核對人1 | AC2: 核對人2 | AD2: 核對人3
A3: 1 | B3: 1150504 | C3: 1150502 | D3: 新峰開發股份有限公司 | E3: 24862822 | F3: AA75665907 | G3: 二收銀-(二聯式收銀機統一發票) | H3: 日用品 | I3: 1 | J3: 1243 | K3: =J3*I3 -> 1243 | L3: 1243 | M3: =L3/1.05 -> 1183.8095 | N3: 59 | P3: 黃珮綺 | V3: 1 | W3: 1150504 | X3: 1150504 | Y3: 勞動部職業安全衛生署N&M貿易第1櫃 | Z3: 8760 | AA3: 胡羽萱
A4: 2 | B4: 1150511 | C4: 1150505 | D4: 石二鍋 | E4: 87230113 | F4: BG63470947 | G4: 電子發票-(電子發票證明聯) | H4: 餐費 | I4: 1 | J4: 1261 | K4: =J4*I4 -> 1261 | L4: 1239 | M4: =L4/1.05 -> 1180 | N4: 59 | P4: 黃珮綺 | V4: 2 | W4: 1150505 | X4: 1150426 | Y4: BLW-0151-汽車保險 | Z4: 12534 | AA4: 林祐竹
A5: 3 | B5: 1150511 | C5: 1150509 | D5: 來來龍鳳城 | E5: 92329635 | F5: AA74863017 | G5: 二收銀-(二聯式收銀機統一發票) | H5: 餐費 | I5: 1 | J5: 3350 | K5: =J5*I5 -> 3350 | L5: 3350 | M5: =L5/1.05 -> 3190.4762 | N5: 160 | P5: 黃珮綺 | V5: 3 | W5: 1150505 | X5: 1150426 | Y5: BLW-0151-汽車強制險 | Z5: 1681 | AA5: 林祐竹
A6: 4 | B6: 1150518 | C6: 1150510 | D6: 黃駿福活蝦有限公司 | E6: 24879540 | F6: BM43372355 | G6: 電子發票-(電子發票證明聯) | H6: 餐費 | I6: 1 | J6: 7076 | K6: =J6*I6 -> 7076 | L6: 7430 | M6: =L6/1.05 -> 7076.1905 | N6: 354 | P6: 黃珮綺 | V6: 4 | W6: 1150505 | X6: 1150407 | Y6: KEU-2727-汽車保險 | Z6: 27093 | AA6: 林祐竹
A7: 5 | B7: 1150518 | C7: 1150517 | D7: 和牛涮 | E7: 60242301 | F7: BG62499223 | G7: 電子發票-(電子發票證明聯) | H7: 餐費 | I7: 1 | J7: 1355 | K7: =J7*I7 -> 1355 | L7: 1491 | M7: =L7/1.05 -> 1420 | N7: 71 | P7: 黃珮綺 | V7: 5 | W7: 1150505 | X7: 1150427 | Y7: KEU-2727-汽車強制險 | Z7: 7092 | AA7: 林祐竹
A8: 6 | B8: 1150518 | C8: 1150511 | D8: 順億 | E8: 94862374 | F8: BA32165755 | G8: 電子發票-(電子發票證明聯) | H8: 餐費 | I8: 1 | J8: 998 | K8: =J8*I8 -> 998 | L8: 1048 | M8: =L8/1.05 -> 998.09524 | N8: 50 | P8: 黃珮綺 | V8: 6 | W8: 1150505 | X8: 1150508 | Y8: BCH-9100-汽車保險 | Z8: 23601 | AA8: 林祐竹
A9: 7 | B9: 1150518 | C9: 1150515 | D9: 爭鮮餐飲 | E9: 96813011 | F9: AQ77386535 | G9: 電子發票-(電子發票證明聯) | H9: 餐費 | I9: 1 | J9: 914 | K9: =J9*I9 -> 914 | L9: 960 | M9: =L9/1.05 -> 914.28571 | N9: 46 | P9: 黃珮綺 | V9: 7 | W9: 1150505 | X9: 1150427 | Y9: BCH-9100-汽車強制險 | Z9: 681 | AA9: 林祐竹
A10: 8 | B10: 1150522 | C10: 1150518 | D10: 藏壽司 | E10: 92656237 | F10: AE60755726 | G10: 電子發票-(電子發票證明聯) | H10: 餐費 | I10: 1 | J10: 493 | K10: =J10*I10 -> 493 | L10: 493 | M10: =L10/1.05 -> 469.52381 | N10: 23 | P10: 林祐竹 | V10: 8 | W10: 1150505 | X10: 1150430 | Y10: KEU-2727-汽車檢驗費 | Z10: 600 | AA10: 林祐竹
A11: 9 | B11: 1150525 | C11: 1150520 | D11: 鴻羽餐飲 | E11: 91023832 | F11: BM43845674 | G11: 電子發票-(電子發票證明聯) | H11: 餐費 | I11: 1 | J11: 3986 | K11: =J11*I11 -> 3986 | L11: 4185 | M11: =L11/1.05 -> 3985.7143 | N11: 199 | P11: 黃珮綺 | V11: 9 | W11: 1150505 | X11: 1150504 | Y11: 郵資券 | Z11: 16 | AA11: 林祐竹
A12: 10 | B12: 1150529 | C12: 1150524 | D12: 乾杯 | E12: 53531132 | F12: BD07456314 | G12: 電子發票-(電子發票證明聯) | H12: 餐費 | I12: 1 | J12: 2462 | K12: =J12*I12 -> 2462 | L12: 2462 | M12: =L12/1.05 -> 2344.7619 | N12: 117 | P12: 林祐竹 | V12: 10 | W12: 1150505 | X12: 1150505 | Y12: 郵資券 | Z12: 8 | AA12: 林祐竹
A13: 11 | B13: 1150603 | C13: 1150602 | D13: One&One燒肉 頭份 | E13: 95277809 | F13: BQ00287054 | G13: 電子發票-(電子發票證明聯) | H13: 餐費 | I13: 1 | J13: 2204 | K13: =J13*I13 -> 2204 | L13: 2314 | M13: =L13/1.05 -> 2203.8095 | N13: 110 | P13: 黃珮綺 | V13: 11 | W13: 1150505 | X13: 1150505 | Y13: 115年華翊第3櫃商港服務費 | Z13: 1368 | AA13: 林祐竹
A14: 12 | K14: =J14*I14 -> 0 | M14: =L14/1.05 -> 0 | N14: =L14-M14 -> 0 | V14: 12 | W14: 1150513 | X14: 1150513 | Y14: 手套 | Z14: 5000 | AA14: 林祐竹
A15: 13 | K15: =J15*I15 -> 0 | M15: =L15/1.05 -> 0 | N15: =L15-M15 -> 0 | V15: 13 | W15: 1150513 | X15: 1150513 | Y15: 手套 | Z15: 1600 | AA15: 林祐竹
A16: 14 | K16: =J16*I16 -> 0 | M16: =L16/1.05 -> 0 | N16: =L16-M16 -> 0 | V16: 14 | W16: 1150514 | X16: 1150513 | Y16: 順豐運費 | Z16: 155 | AA16: 林祐竹
A17: 15 | K17: =J17*I17 -> 0 | M17: =L17/1.05 -> 0 | N17: =L17-M17 -> 0 | V17: 15 | W17: 1150514 | X17: 1150513 | Y17: 順豐進口關稅 | Z17: 23 | AA17: 林祐竹
A18: 16 | K18: =J18*I18 -> 0 | M18: =L18/1.05 -> 0 | N18: =L18-M18 -> 0 | V18: 16 | W18: 1150516 | X18: 1150515 | Y18: BLW-0151驗車費 | Z18: 450 | AA18: 黃珮綺
A19: 17 | K19: =J19*I19 -> 0 | M19: =L19/1.05 -> 0 | N19: =L19-M19 -> 0 | V19: 17 | W19: 1150516 | X19: 1150515 | Y19: BCH-9100驗車費 | Z19: 450 | AA19: 黃珮綺
A20: 18 | K20: =J20*I20 -> 0 | M20: =L20/1.05 -> 0 | N20: =L20-M20 -> 0 | V20: 18 | W20: 1150520 | X20: 1150519 | Y20: 郵資券 | Z20: 60 | AA20: 林祐竹
A21: 19 | K21: =J21*I21 -> 0 | M21: =L21/1.05 -> 0 | N21: =L21-M21 -> 0 | V21: 19 | W21: 1150523 | X21: 1150521 | Y21: 115年翔株式第6櫃商港服務費 | Z21: 1368 | AA21: 林祐竹
A22: 20 | K22: =J22*I22 -> 0 | M22: =L22/1.05 -> 0 | N22: =L22-M22 -> 0 | V22: 20 | W22: 1150527 | X22: 1150526 | Y22: 115年上海拆胎機第一櫃商港服務費 | Z22: 263 | AA22: 林祐竹
A23: 21 | K23: =J23*I23 -> 0 | M23: =L23/1.05 -> 0 | N23: =L23-M23 -> 0 | V23: 21 | W23: 1150527 | X23: 1150525 | Y23: 郵資券 | Z23: 2800 | AA23: 林祐竹
A24: 22 | K24: =J24*I24 -> 0 | M24: =L24/1.05 -> 0 | N24: =L24-M24 -> 0 | V24: 22 | W24: 1150527 | X24: 1150519 | Y24: 郵資券 | Z24: 8 | AA24: 林祐竹
A25: 23 | K25: =J25*I25 -> 0 | M25: =L25/1.05 -> 0 | N25: =L25-M25 -> 0 | V25: 23 | W25: 1150527 | X25: 1150521 | Y25: 郵資券 | Z25: 80 | AA25: 林祐竹
A26: 24 | K26: =J26*I26 -> 0 | M26: =L26/1.05 -> 0 | N26: =L26-M26 -> 0 | V26: 24 | W26: 1150527 | Y26: 115年4月員工健保費 | Z26: 17615 | AA26: 林祐竹
A27: 25 | K27: =J27*I27 -> 0 | M27: =L27/1.05 -> 0 | N27: =L27-M27 -> 0 | V27: 25 | W27: 1150529 | X27: 1150529 | Y27: 114年度營利事業所得稅 | Z27: 547492 | AA27: 林祐竹
A28: 26 | K28: =J28*I28 -> 0 | M28: =L28/1.05 -> 0 | N28: =L28-M28 -> 0 | V28: 26 | W28: 1150529 | Y28: 115年4月員工勞工退休金 | Z28: 10620 | AA28: 林祐竹
A29: 27 | K29: =J29*I29 -> 0 | M29: =L29/1.05 -> 0 | N29: =L29-M29 -> 0 | V29: 27 | W29: 1150529 | Y29: 115年4月員工勞保費 | Z29: 20300 | AA29: 林祐竹
A30: 28 | K30: =J30*I30 -> 0 | M30: =L30/1.05 -> 0 | N30: =L30-M30 -> 0 | V30: 28 | W30: 1150530 | X30: 1150528 | Y30: 郵資券 | Z30: 2976 | AA30: 林祐竹
A31: 29 | K31: =J31*I31 -> 0 | M31: =L31/1.05 -> 0 | N31: =L31-M31 -> 0 | V31: 29 | W31: 1150530 | X31: 1150528 | Y31: 郵票 | Z31: 2800 | AA31: 林祐竹
A32: 30 | K32: =J32*I32 -> 0 | M32: =L32/1.05 -> 0 | N32: =L32-M32 -> 0 | V32: 30 | W32: 1150530 | X32: 1150528 | Y32: 郵資券 | Z32: 16 | AA32: 林祐竹
A33: 31 | K33: =J33*I33 -> 0 | M33: =L33/1.05 -> 0 | N33: =L33-M33 -> 0 | V33: 31 | W33: 1150530 | X33: 1150529 | Y33: 郵票 | Z33: 800 | AA33: 林祐竹
A34: 32 | K34: =J34*I34 -> 0 | M34: =L34/1.05 -> 0 | N34: =L34-M34 -> 0 | V34: 32 | W34: 1150530 | X34: 1150529 | Y34: 車牌貼紙 | Z34: 750 | AA34: 林祐竹
A35: 33 | K35: =J35*I35 -> 0 | M35: =L35/1.05 -> 0 | N35: =L35-M35 -> 0 | V35: 33 | W35: 1150530 | Y35: 餐費 | AA35: 林祐竹
A36: 34 | K36: =J36*I36 -> 0 | M36: =L36/1.05 -> 0 | N36: =L36-M36 -> 0 | V36: 34 | W36: 1150530 | X36: 1150516 | Y36: 餐費 | Z36: 990 | AA36: 林祐竹
A37: 35 | K37: =J37*I37 -> 0 | M37: =L37/1.05 -> 0 | N37: =L37-M37 -> 0 | V37: 35 | W37: 1150530 | X37: 1150525 | Y37: 餐費 | Z37: 2850 | AA37: 林祐竹
A38: 36 | K38: =J38*I38 -> 0 | M38: =L38/1.05 -> 0 | N38: =L38-M38 -> 0 | V38: 36 | W38: 1150530 | Y38: 餐費 | AA38: 林祐竹
A39: 37 | K39: =J39*I39 -> 0 | M39: =L39/1.05 -> 0 | N39: =L39-M39 -> 0 | V39: 37 | W39: 1150603 | X39: 1150601 | Y39: 郵資 | Z39: 80 | AA39: 黃珮綺
A40: 38 | K40: =J40*I40 -> 0 | M40: =L40/1.05 -> 0 | N40: =L40-M40 -> 0 | V40: 38 | W40: 1150603 | X40: 1150601 | Y40: 餐費 | Z40: 5600 | AA40: 黃珮綺
...

Sheet 私人收據
E1: 私人雜項收據 | K1: 私人醫療收據
A2: 序號 | B2: 登入日期 | C2: 日期 | D2: 品名 | E2: 金額 | F2: 工作人員 | H2: 登入日期 | I2: 日期 | J2: 品名 | K2: 金額 | L2: 工作人員
A3: 1 | H3: 1150505 | I3: 1150504 | J3: 宏仁診所-陳婉玲 | K3: 250 | L3: 林祐竹
A4: 2 | H4: 1150523 | I4: 1150522 | J4: 哈佛牙醫-陳婉玲 | K4: 150 | L4: 林祐竹
A5: 3 | H5: 1150523 | I5: 1150521 | J5: 臺大醫院-胡振新 | K5: 220 | L5: 林祐竹
A6: 4 | H6: 1150609 | I6: 1150606 | J6: 新愛兒診所-胡允霏 | K6: 200 | L6: 黃珮綺
A7: 5 | H7: 1150609 | I7: 1150606 | J7: 新愛兒診所-胡允澤 | K7: 200 | L7: 黃珮綺
A8: 6
A9: 7
A10: 8
A11: 9
A12: 10
A13: 11
A14: 12
A15: 13
A16: 14
A17: 15
A18: 16
A19: 17
... A147: 145

Sheet 上期留抵發票明細
G1: =SUM(G3:G47) -> 29985 | H1: 401報表 | I1: 0 | N1: 中華全佑 | W1: 稅金回推發票總額
C2: 月份 | D2: 發票號碼 | E2: 總額 | F2: 未稅金額 | G2: 稅額 | H2: 核對人1 | I2: 核對人2 | J2: 核對人3 | K2: 已申報 | N2: 銷項稅額 | O2: 進項稅額 | P2: 上期留抵稅額 | Q2: 繳稅額(負數不用繳費) | S2: 可開總金額 | U2: 可開(未稅)總金額 | W2: =稅金/0.05*1.05
C3: 03-04 | D3: ZE14300177 | E3: 46998 | F3: =E3/1.05 -> 44760 | G3: 2238 | N3: =+銷項!N1+銷項!BD1+銷項!AI1+銷項!BR1 -> 41108.333 | O3: =+'中華全佑27911467-營業稅扣抵'!O1 -> 23615.333 | P3: =+G1+I1 -> 29985 | Q3: =+N3-O3-P3 -> -12492 | S3: =U3*1.05 -> -262332 | U3: =Q3/0.05 -> -249840
C4: 03-04 | D4: ABI11150634636 | E4: 320512 | F4: 305249.52 | G4: 15262 | H4: 在連偉那 | W4: 發票總額回推稅金
C5: 03-04 | D5: ZE14302547 | G5: 12485 | H5: 發票未來 | W5: =發票總額/1.05*0.05
